Workbook

Sheet Sheet1
S1: =TEXT(S2,"ddd") -> Mon | T1: =TEXT(T2,"ddd") -> Tue | U1: =TEXT(U2,"ddd") -> Wed | V1: =TEXT(V2,"ddd") -> Thu | W1: =TEXT(W2,"ddd") -> Fri | X1: =TEXT(X2,"ddd") -> Sat | Y1: =TEXT(Y2,"ddd") -> Sun | Z1: =TEXT(Z2,"ddd") -> Mon | ... AV1: =TEXT(AV2,"ddd") -> Tue
A2: Emp ID | B2: Name | C2: Designation | D2: Department | E2: Mobile No | F2: UAN No | G2: EPF No | H2: Account No | I2: EPF No | J2: ESI No | K2: PAN No | L2: Adhar No | M2: Address | N2: City | O2: Pin Code | P2: Joining Date | Q2: Shift | R2: Email | S2: 45901 | T2: 45902 | U2: 45903 | V2: 45904 | W2: 45905 | X2: 45906 | Y2: 45907 | Z2: 45908 | AA2: 45909 | AB2: 45910 | AC2: 45911 | AD2: 45912 | AE2: 45913 | AF2: 45914 | AG2: 45915 | AH2: 45916 | AI2: 45917 | AJ2: 45918 | AK2: 45919 | AL2: 45920 | AM2: 45921 | AN2: 45922 | AO2: 45923 | AP2: 45924 | AQ2: 45925 | AR2: 45926 | AS2: 45927 | AT2: 45928 | AU2: 45929 | AV2: 45930 | AW2: Presents | AX2: Absents | AY2: Halfdays | AZ2: Leaves | BA2: Week Offs | BB2: Holidays | BC2: Payable Days | BD2: Basic Salary | BE2: Actual Basic | BF2: DA | BG2: HRA | BH2: TA | BI2: Inentive | BJ2: Gross Salary | BK2: EPF 12% | BL2: ESI 0.75% | BM2: EPF 3.67% | BN2: EPS 8.33% | BO2: ESI 3.25% | BP2: PT | BQ2: TDS | BR2: Advance | BS2: Net Salary
A3: E00001 | B3: Arjun Sharma | C3: MIS Executive | D3: Sales | E3: 1644768735 | F3: 106703537971 | G3: 1471610171 | H3: 9038282681 | I3: 1471610171 | J3: 8851056157 | K3: EAQAB1644N | L3: 391340467909 | M3: H.No. 97, Borde Nagar, Kozhikode 485454 | N3: Hubliâ€“Dharwad | O3: 389592 | P3: 43727 | Q3: Day | R3: goleinaaya@hotmail.com | S3: =VLOOKUP($A3&S$2,Sheet2!$D$1:$F$601,3,0) -> A | T3: =VLOOKUP($A3&T$2,Sheet2!$D$1:$F$601,3,0) -> P | U3: =VLOOKUP($A3&U$2,Sheet2!$D$1:$F$601,3,0) -> P | V3: =VLOOKUP($A3&V$2,Sheet2!$D$1:$F$601,3,0) -> P | W3: =VLOOKUP($A3&W$2,Sheet2!$D$1:$F$601,3,0) -> P | X3: =VLOOKUP($A3&X$2,Sheet2!$D$1:$F$601,3,0) -> P | Y3: WO | Z3: =VLOOKUP($A3&Z$2,Sheet2!$D$1:$F$601,3,0) -> P | AA3: =VLOOKUP($A3&AA$2,Sheet2!$D$1:$F$601,3,0) -> P | AB3: =VLOOKUP($A3&AB$2,Sheet2!$D$1:$F$601,3,0) -> P | AC3: =VLOOKUP($A3&AC$2,Sheet2!$D$1:$F$601,3,0) -> A | AD3: =VLOOKUP($A3&AD$2,Sheet2!$D$1:$F$601,3,0) -> P | AE3: =VLOOKUP($A3&AE$2,Sheet2!$D$1:$F$601,3,0) -> P | AF3: WO | AG3: =VLOOKUP($A3&AG$2,Sheet2!$D$1:$F$601,3,0) -> L | AH3: =VLOOKUP($A3&AH$2,Sheet2!$D$1:$F$601,3,0) -> P | AI3: =VLOOKUP($A3&AI$2,Sheet2!$D$1:$F$601,3,0) -> L | AJ3: =VLOOKUP($A3&AJ$2,Sheet2!$D$1:$F$601,3,0) -> P | AK3: =VLOOKUP($A3&AK$2,Sheet2!$D$1:$F$601,3,0) -> P | AL3: =VLOOKUP($A3&AL$2,Sheet2!$D$1:$F$601,3,0) -> A | AM3: WO | AN3: =VLOOKUP($A3&AN$2,Sheet2!$D$1:$F$601,3,0) -> L | AO3: =VLOOKUP($A3&AO$2,Sheet2!$D$1:$F$601,3,0) -> L | AP3: =VLOOKUP($A3&AP$2,Sheet2!$D$1:$F$601,3,0) -> P | AQ3: =VLOOKUP($A3&AQ$2,Sheet2!$D$1:$F$601,3,0) -> P | AR3: =VLOOKUP($A3&AR$2,Sheet2!$D$1:$F$601,3,0) -> P | AS3: =VLOOKUP($A3&AS$2,Sheet2!$D$1:$F$601,3,0) -> P | AT3: WO | AU3: =VLOOKUP($A3&AU$2,Sheet2!$D$1:$F$601,3,0) -> P | AV3: =VLOOKUP($A3&AV$2,Sheet2!$D$1:$F$601,3,0) -> P | AW3: =COUNTIF(S3:AV3,"P") -> 19 | AX3: =COUNTIF(S3:AV3,"A") -> 3 | AY3: =COUNTIF(S3:AV3,"H") -> 0 | AZ3: =COUNTIF(S3:AV3,"L") -> 4 | BA3: =COUNTIF(S3:AV3,"WO") -> 4 | BB3: =COUNTIF(S3:AV3,"HO") -> 0 | BC3: =SUM(AW3:BB3)-AX3-IF(AZ3>1,AZ3-1,0)-(AY3/2) -> 24 | BD3: 15000 | BE3: =BD3/30*BC3 -> 12000 | BF3: =BE3*20% -> 2400 | BG3: =BE3*40% -> 4800 | BH3: 1734 | BI3: =VLOOKUP(A3,Sheet3!$A$1:$E$21,5,0) -> 0 | BJ3: =SUM(BE3:BI3) -> 20934 | BK3: =IF(SUM(BE3:BF3)>=15000,1800,(SUM(BE3:BF3)*12%)) -> 1728 | BL3: =IF(BJ3>21000,0,BJ3*0.75%) -> 157.005 | BM3: =IF(SUM(BE3:BF3)>=15000,550.5,(SUM(BE3:BF3)*3.67%)) -> 528.48 | BN3: =IF(SUM(BE3:BF3)>=15000,1249.5,SUM(BE3:BF3)*8.33%) -> 1199.52 | BO3: =IF(BJ3>=21000,0,BJ3*3.25%) -> 680.355 | BP3: =IF(BJ3>25000,200,IF(BJ3>20000,150,IF(BJ3>15000,100,0))) -> 150 | BQ3: =IF((BJ3*12)<=400000,0, IF((BJ3*12)<=800000,((BJ3*12)-400000)*5%, IF((BJ3*12)<=1200000,20000+((BJ3*12)-800000)*10%, IF((BJ3*12)<=1600000,60000+((BJ3*12)-1200000)*15%, IF((BJ3*12)<=2000000,120000+((BJ3*12)-1600000)*20%, IF((BJ3*12)<=2400000,200000+((BJ3*12)-2000000)*25%, IF((BJ3*12)>2400000,300000+((BJ3*12)-2400000)*30%)))))))/12 -> 0 | BR3: 0 | BS3: =BJ3-BK3-BL3-BP3-BQ3-BR3 -> 18898.995
A4: E00002 | B4: Amit Verma | C4: Officer | D4: HR | E4: 5268118934 | F4: 257161423294 | G4: 7093422718 | H4: 6423779496 | I4: 7093422718 | J4: 6807616715 | K4: ZBUBV5882E | L4: 871900147341 | M4: H.No. 48, Saxena Marg, Sri Ganganagar 341471 | N4: Bokaro | O4: 841143 | P4: 44790 | Q4: Day | R4: kundalakshit@grover.biz | S4: =VLOOKUP($A4&S$2,Sheet2!$D$1:$F$601,3,0) -> P | T4: =VLOOKUP($A4&T$2,Sheet2!$D$1:$F$601,3,0) -> P | U4: =VLOOKUP($A4&U$2,Sheet2!$D$1:$F$601,3,0) -> L | V4: =VLOOKUP($A4&V$2,Sheet2!$D$1:$F$601,3,0) -> P | W4: =VLOOKUP($A4&W$2,Sheet2!$D$1:$F$601,3,0) -> P | X4: =VLOOKUP($A4&X$2,Sheet2!$D$1:$F$601,3,0) -> P | Y4: WO | Z4: =VLOOKUP($A4&Z$2,Sheet2!$D$1:$F$601,3,0) -> P | AA4: =VLOOKUP($A4&AA$2,Sheet2!$D$1:$F$601,3,0) -> A | AB4: =VLOOKUP($A4&AB$2,Sheet2!$D$1:$F$601,3,0) -> P | AC4: =VLOOKUP($A4&AC$2,Sheet2!$D$1:$F$601,3,0) -> P | AD4: =VLOOKUP($A4&AD$2,Sheet2!$D$1:$F$601,3,0) -> L | AE4: =VLOOKUP($A4&AE$2,Sheet2!$D$1:$F$601,3,0) -> P | AF4: WO | AG4: =VLOOKUP($A4&AG$2,Sheet2!$D$1:$F$601,3,0) -> A | AH4: =VLOOKUP($A4&AH$2,Sheet2!$D$1:$F$601,3,0) -> P | AI4: =VLOOKUP($A4&AI$2,Sheet2!$D$1:$F$601,3,0) -> P | AJ4: =VLOOKUP($A4&AJ$2,Sheet2!$D$1:$F$601,3,0) -> P | AK4: =VLOOKUP($A4&AK$2,Sheet2!$D$1:$F$601,3,0) -> A | AL4: =VLOOKUP($A4&AL$2,Sheet2!$D$1:$F$601,3,0) -> A | AM4: WO | AN4: =VLOOKUP($A4&AN$2,Sheet2!$D$1:$F$601,3,0) -> A | AO4: =VLOOKUP($A4&AO$2,Sheet2!$D$1:$F$601,3,0) -> P | AP4: =VLOOKUP($A4&AP$2,Sheet2!$D$1:$F$601,3,0) -> P | AQ4: =VLOOKUP($A4&AQ$2,Sheet2!$D$1:$F$601,3,0) -> P | AR4: =VLOOKUP($A4&AR$2,Sheet2!$D$1:$F$601,3,0) -> P | AS4: =VLOOKUP($A4&AS$2,Sheet2!$D$1:$F$601,3,0) -> P | AT4: WO | AU4: =VLOOKUP($A4&AU$2,Sheet2!$D$1:$F$601,3,0) -> P | AV4: =VLOOKUP($A4&AV$2,Sheet2!$D$1:$F$601,3,0) -> P | AW4: =COUNTIF(S4:AV4,"P") -> 19 | AX4: =COUNTIF(S4:AV4,"A") -> 5 | AY4: =COUNTIF(S4:AV4,"H") -> 0 | AZ4: =COUNTIF(S4:AV4,"L") -> 2 | BA4: =COUNTIF(S4:AV4,"WO") -> 4 | BB4: =COUNTIF(S4:AV4,"HO") -> 0 | BC4: =SUM(AW4:BB4)-AX4-IF(AZ4>1,AZ4-1,0)-(AY4/2) -> 24 | BD4: 11000 | BE4: =BD4/30*BC4 -> 8800 | BF4: =BE4*20% -> 1760 | BG4: =BE4*40% -> 3520 | BH4: 2900 | BI4: =VLOOKUP(A4,Sheet3!$A$1:$E$21,5,0) -> 0 | BJ4: =SUM(BE4:BI4) -> 16980 | BK4: =IF(SUM(BE4:BF4)>=15000,1800,(SUM(BE4:BF4)*12%)) -> 1267.2 | BL4: =IF(BJ4>21000,0,BJ4*0.75%) -> 127.35 | BM4: =IF(SUM(BE4:BF4)>=15000,550.5,(SUM(BE4:BF4)*3.67%)) -> 387.552 | BN4: =IF(SUM(BE4:BF4)>=15000,1249.5,SUM(BE4:BF4)*8.33%) -> 879.648 | BO4: =IF(BJ4>=21000,0,BJ4*3.25%) -> 551.85 | BP4: =IF(BJ4>25000,200,IF(BJ4>20000,150,IF(BJ4>15000,100,0))) -> 100 | BQ4: =IF((BJ4*12)<=400000,0, IF((BJ4*12)<=800000,((BJ4*12)-400000)*5%, IF((BJ4*12)<=1200000,20000+((BJ4*12)-800000)*10%, IF((BJ4*12)<=1600000,60000+((BJ4*12)-1200000)*15%, IF((BJ4*12)<=2000000,120000+((BJ4*12)-1600000)*20%, IF((BJ4*12)<=2400000,200000+((BJ4*12)-2000000)*25%, IF((BJ4*12)>2400000,300000+((BJ4*12)-2400000)*30%)))))))/12 -> 0 | BR4: 0 | BS4: =BJ4-BK4-BL4-BP4-BQ4-BR4 -> 15485.45
A5: E00003 | B5: Rohit Singh | C5: Accountant | D5: IT | E5: 0566890300 | F5: 706014545294 | G5: 8495458915 | H5: 3559907319 | I5: 8495458915 | J5: 9904118409 | K5: TJGVH5342J | L5: 589222384145 | M5: H.No. 19, Bera Path, Patna-921830 | N5: Sagar | O5: 711990 | P5: 43178 | Q5: Day | R5: alisha12@gmail.com | S5: =VLOOKUP($A5&S$2,Sheet2!$D$1:$F$601,3,0) -> P | T5: =VLOOKUP($A5&T$2,Sheet2!$D$1:$F$601,3,0) -> P | U5: =VLOOKUP($A5&U$2,Sheet2!$D$1:$F$601,3,0) -> P | V5: =VLOOKUP($A5&V$2,Sheet2!$D$1:$F$601,3,0) -> A | W5: =VLOOKUP($A5&W$2,Sheet2!$D$1:$F$601,3,0) -> A | X5: =VLOOKUP($A5&X$2,Sheet2!$D$1:$F$601,3,0) -> P | Y5: WO | Z5: =VLOOKUP($A5&Z$2,Sheet2!$D$1:$F$601,3,0) -> P | AA5: =VLOOKUP($A5&AA$2,Sheet2!$D$1:$F$601,3,0) -> P | AB5: =VLOOKUP($A5&AB$2,Sheet2!$D$1:$F$601,3,0) -> A | AC5: =VLOOKUP($A5&AC$2,Sheet2!$D$1:$F$601,3,0) -> P | AD5: =VLOOKUP($A5&AD$2,Sheet2!$D$1:$F$601,3,0) -> P | AE5: =VLOOKUP($A5&AE$2,Sheet2!$D$1:$F$601,3,0) -> A | AF5: WO | AG5: =VLOOKUP($A5&AG$2,Sheet2!$D$1:$F$601,3,0) -> P | AH5: =VLOOKUP($A5&AH$2,Sheet2!$D$1:$F$601,3,0) -> L | AI5: =VLOOKUP($A5&AI$2,Sheet2!$D$1:$F$601,3,0) -> A | AJ5: =VLOOKUP($A5&AJ$2,Sheet2!$D$1:$F$601,3,0) -> P | AK5: =VLOOKUP($A5&AK$2,Sheet2!$D$1:$F$601,3,0) -> L | AL5: =VLOOKUP($A5&AL$2,Sheet2!$D$1:$F$601,3,0) -> P | AM5: WO | AN5: =VLOOKUP($A5&AN$2,Sheet2!$D$1:$F$601,3,0) -> L | AO5: =VLOOKUP($A5&AO$2,Sheet2!$D$1:$F$601,3,0) -> P | AP5: =VLOOKUP($A5&AP$2,Sheet2!$D$1:$F$601,3,0) -> L | AQ5: =VLOOKUP($A5&AQ$2,Sheet2!$D$1:$F$601,3,0) -> P | AR5: =VLOOKUP($A5&AR$2,Sheet2!$D$1:$F$601,3,0) -> P | AS5: =VLOOKUP($A5&AS$2,Sheet2!$D$1:$F$601,3,0) -> A | AT5: WO | AU5: =VLOOKUP($A5&AU$2,Sheet2!$D$1:$F$601,3,0) -> P | AV5: =VLOOKUP($A5&AV$2,Sheet2!$D$1:$F$601,3,0) -> P | AW5: =COUNTIF(S5:AV5,"P") -> 16 | AX5: =COUNTIF(S5:AV5,"A") -> 6 | AY5: =COUNTIF(S5:AV5,"H") -> 0 | AZ5: =COUNTIF(S5:AV5,"L") -> 4 | BA5: =COUNTIF(S5:AV5,"WO") -> 4 | BB5: =COUNTIF(S5:AV5,"HO") -> 0 | BC5: =SUM(AW5:BB5)-AX5-IF(AZ5>1,AZ5-1,0)-(AY5/2) -> 21 | BD5: 14000 | BE5: =BD5/30*BC5 -> 9800 | BF5: =BE5*20% -> 1960 | BG5: =BE5*40% -> 3920 | BH5: 1449 | BI5: =VLOOKUP(A5,Sheet3!$A$1:$E$21,5,0) -> 5994.45 | BJ5: =SUM(BE5:BI5) -> 23123.45 | BK5: =IF(SUM(BE5:BF5)>=15000,1800,(SUM(BE5:BF5)*12%)) -> 1411.2 | BL5: =IF(BJ5>21000,0,BJ5*0.75%) -> 0 | BM5: =IF(SUM(BE5:BF5)>=15000,550.5,(SUM(BE5:BF5)*3.67%)) -> 431.592 | BN5: =IF(SUM(BE5:BF5)>=15000,1249.5,SUM(BE5:BF5)*8.33%) -> 979.608 | BO5: =IF(BJ5>=21000,0,BJ5*3.25%) -> 0 | BP5: =IF(BJ5>25000,200,IF(BJ5>20000,150,IF(BJ5>15000,100,0))) -> 150 | BQ5: =IF((BJ5*12)<=400000,0, IF((BJ5*12)<=800000,((BJ5*12)-400000)*5%, IF((BJ5*12)<=1200000,20000+((BJ5*12)-800000)*10%, IF((BJ5*12)<=1600000,60000+((BJ5*12)-1200000)*15%, IF((BJ5*12)<=2000000,120000+((BJ5*12)-1600000)*20%, IF((BJ5*12)<=2400000,200000+((BJ5*12)-2000000)*25%, IF((BJ5*12)>2400000,300000+((BJ5*12)-2400000)*30%)))))))/12 -> 0 | BR5: 3000 | BS5: =BJ5-BK5-BL5-BP5-BQ5-BR5 -> 18562.25
A6: E00004 | B6: Suresh Kumar | C6: MIS Executive | D6: IT | E6: 1571309616 | F6: 308014527615 | G6: 6633785225 | H6: 6866425426 | I6: 6633785225 | J6: 5117145225 | K6: ULEHS5259C | L6: 508367384546 | M6: 79/84, Gill Ganj, Durgapur 441138 | N6: Malda | O6: 118638 | P6: 42488 | Q6: Day | R6: jayantbhatnagar@yahoo.com | S6: =VLOOKUP($A6&S$2,Sheet2!$D$1:$F$601,3,0) -> P | T6: =VLOOKUP($A6&T$2,Sheet2!$D$1:$F$601,3,0) -> A | U6: =VLOOKUP($A6&U$2,Sheet2!$D$1:$F$601,3,0) -> P | V6: =VLOOKUP($A6&V$2,Sheet2!$D$1:$F$601,3,0) -> P | W6: =VLOOKUP($A6&W$2,Sheet2!$D$1:$F$601,3,0) -> P | X6: =VLOOKUP($A6&X$2,Sheet2!$D$1:$F$601,3,0) -> L | Y6: WO | Z6: =VLOOKUP($A6&Z$2,Sheet2!$D$1:$F$601,3,0) -> P | AA6: =VLOOKUP($A6&AA$2,Sheet2!$D$1:$F$601,3,0) -> A | AB6: =VLOOKUP($A6&AB$2,Sheet2!$D$1:$F$601,3,0) -> P | AC6: =VLOOKUP($A6&AC$2,Sheet2!$D$1:$F$601,3,0) -> P | AD6: =VLOOKUP($A6&AD$2,Sheet2!$D$1:$F$601,3,0) -> P | AE6: =VLOOKUP($A6&AE$2,Sheet2!$D$1:$F$601,3,0) -> P | AF6: WO | AG6: =VLOOKUP($A6&AG$2,Sheet2!$D$1:$F$601,3,0) -> P | AH6: =VLOOKUP($A6&AH$2,Sheet2!$D$1:$F$601,3,0) -> L | AI6: =VLOOKUP($A6&AI$2,Sheet2!$D$1:$F$601,3,0) -> P | AJ6: =VLOOKUP($A6&AJ$2,Sheet2!$D$1:$F$601,3,0) -> P | AK6: =VLOOKUP($A6&AK$2,Sheet2!$D$1:$F$601,3,0) -> A | AL6: =VLOOKUP($A6&AL$2,Sheet2!$D$1:$F$601,3,0) -> L | AM6: WO | AN6: =VLOOKUP($A6&AN$2,Sheet2!$D$1:$F$601,3,0) -> P | AO6: =VLOOKUP($A6&AO$2,Sheet2!$D$1:$F$601,3,0) -> A | AP6: =VLOOKUP($A6&AP$2,Sheet2!$D$1:$F$601,3,0) -> P | AQ6: =VLOOKUP($A6&AQ$2,Sheet2!$D$1:$F$601,3,0) -> P | AR6: =VLOOKUP($A6&AR$2,Sheet2!$D$1:$F$601,3,0) -> P | AS6: =VLOOKUP($A6&AS$2,Sheet2!$D$1:$F$601,3,0) -> P | AT6: WO | AU6: =VLOOKUP($A6&AU$2,Sheet2!$D$1:$F$601,3,0) -> P | AV6: =VLOOKUP($A6&AV$2,Sheet2!$D$1:$F$601,3,0) -> A | AW6: =COUNTIF(S6:AV6,"P") -> 18 | AX6: =COUNTIF(S6:AV6,"A") -> 5 | AY6: =COUNTIF(S6:AV6,"H") -> 0 | AZ6: =COUNTIF(S6:AV6,"L") -> 3 | BA6: =COUNTIF(S6:AV6,"WO") -> 4 | BB6: =COUNTIF(S6:AV6,"HO") -> 0 | BC6: =SUM(AW6:BB6)-AX6-IF(AZ6>1,AZ6-1,0)-(AY6/2) -> 23 | BD6: 19000 | BE6: =BD6/30*BC6 -> 14566.667 | BF6: =BE6*20% -> 2913.3333 | BG6: =BE6*40% -> 5826.6667 | BH6: 2937 | BI6: =VLOOKUP(A6,Sheet3!$A$1:$E$21,5,0) -> 5971.55 | BJ6: =SUM(BE6:BI6) -> 32215.217 | BK6: =IF(SUM(BE6:BF6)>=15000,1800,(SUM(BE6:BF6)*12%)) -> 1800 | BL6: =IF(BJ6>21000,0,BJ6*0.75%) -> 0 | BM6: =IF(SUM(BE6:BF6)>=15000,550.5,(SUM(BE6:BF6)*3.67%)) -> 550.5 | BN6: =IF(SUM(BE6:BF6)>=15000,1249.5,SUM(BE6:BF6)*8.33%) -> 1249.5 | BO6: =IF(BJ6>=21000,0,BJ6*3.25%) -> 0 | BP6: =IF(BJ6>25000,200,IF(BJ6>20000,150,IF(BJ6>15000,100,0))) -> 200 | BQ6: =IF((BJ6*12)<=400000,0, IF((BJ6*12)<=800000,((BJ6*12)-400000)*5%, IF((BJ6*12)<=1200000,20000+((BJ6*12)-800000)*10%, IF((BJ6*12)<=1600000,60000+((BJ6*12)-1200000)*15%, IF((BJ6*12)<=2000000,120000+((BJ6*12)-1600000)*20%, IF((BJ6*12)<=2400000,200000+((BJ6*12)-2000000)*25%, IF((BJ6*12)>2400000,300000+((BJ6*12)-2400000)*30%)))))))/12 -> 0 | BR6: 0 | BS6: =BJ6-BK6-BL6-BP6-BQ6-BR6 -> 30215.217
A7: E00005 | B7: Vijay Patel | C7: Admin | D7: IT | E7: 5586820751 | F7: 952432582141 | G7: 3033469508 | H7: 4760413935 | I7: 3033469508 | J7: 8837254663 | K7: KWJBD7879O | L7: 375042859785 | M7: 077, Varkey Zila, Bhopal-613953 | N7: Malda | O7: 827389 | P7: 45406 | Q7: Night | R7: basudhanuk@yahoo.com | S7: =VLOOKUP($A7&S$2,Sheet2!$D$1:$F$601,3,0) -> A | T7: =VLOOKUP($A7&T$2,Sheet2!$D$1:$F$601,3,0) -> P | U7: =VLOOKUP($A7&U$2,Sheet2!$D$1:$F$601,3,0) -> P | V7: =VLOOKUP($A7&V$2,Sheet2!$D$1:$F$601,3,0) -> P | W7: =VLOOKUP($A7&W$2,Sheet2!$D$1:$F$601,3,0) -> L | X7: =VLOOKUP($A7&X$2,Sheet2!$D$1:$F$601,3,0) -> P | Y7: WO | Z7: =VLOOKUP($A7&Z$2,Sheet2!$D$1:$F$601,3,0) -> P | AA7: =VLOOKUP($A7&AA$2,Sheet2!$D$1:$F$601,3,0) -> P | AB7: =VLOOKUP($A7&AB$2,Sheet2!$D$1:$F$601,3,0) -> P | AC7: =VLOOKUP($A7&AC$2,Sheet2!$D$1:$F$601,3,0) -> P | AD7: =VLOOKUP($A7&AD$2,Sheet2!$D$1:$F$601,3,0) -> P | AE7: =VLOOKUP($A7&AE$2,Sheet2!$D$1:$F$601,3,0) -> P | AF7: WO | AG7: =VLOOKUP($A7&AG$2,Sheet2!$D$1:$F$601,3,0) -> A | AH7: =VLOOKUP($A7&AH$2,Sheet2!$D$1:$F$601,3,0) -> P | AI7: =VLOOKUP($A7&AI$2,Sheet2!$D$1:$F$601,3,0) -> A | AJ7: =VLOOKUP($A7&AJ$2,Sheet2!$D$1:$F$601,3,0) -> P | AK7: =VLOOKUP($A7&AK$2,Sheet2!$D$1:$F$601,3,0) -> P | AL7: =VLOOKUP($A7&AL$2,Sheet2!$D$1:$F$601,3,0) -> P | AM7: WO | AN7: =VLOOKUP($A7&AN$2,Sheet2!$D$1:$F$601,3,0) -> A | AO7: =VLOOKUP($A7&AO$2,Sheet2!$D$1:$F$601,3,0) -> P | AP7: =VLOOKUP($A7&AP$2,Sheet2!$D$1:$F$601,3,0) -> P | AQ7: =VLOOKUP($A7&AQ$2,Sheet2!$D$1:$F$601,3,0) -> P | AR7: =VLOOKUP($A7&AR$2,Sheet2!$D$1:$F$601,3,0) -> P | AS7: =VLOOKUP($A7&AS$2,Sheet2!$D$1:$F$601,3,0) -> A | AT7: WO | AU7: =VLOOKUP($A7&AU$2,Sheet2!$D$1:$F$601,3,0) -> L | AV7: =VLOOKUP($A7&AV$2,Sheet2!$D$1:$F$601,3,0) -> P | AW7: =COUNTIF(S7:AV7,"P") -> 19 | AX7: =COUNTIF(S7:AV7,"A") -> 5 | AY7: =COUNTIF(S7:AV7,"H") -> 0 | AZ7: =COUNTIF(S7:AV7,"L") -> 2 | BA7: =COUNTIF(S7:AV7,"WO") -> 4 | BB7: =COUNTIF(S7:AV7,"HO") -> 0 | BC7: =SUM(AW7:BB7)-AX7-IF(AZ7>1,AZ7-1,0)-(AY7/2) -> 24 | BD7: 13000 | BE7: =BD7/30*BC7 -> 10400 | BF7: =BE7*20% -> 2080 | BG7: =BE7*40% -> 4160 | BH7: 1404 | BI7: =VLOOKUP(A7,Sheet3!$A$1:$E$21,5,0) -> 0 | BJ7: =SUM(BE7:BI7) -> 18044 | BK7: =IF(SUM(BE7:BF7)>=15000,1800,(SUM(BE7:BF7)*12%)) -> 1497.6 | BL7: =IF(BJ7>21000,0,BJ7*0.75%) -> 135.33 | BM7: =IF(SUM(BE7:BF7)>=15000,550.5,(SUM(BE7:BF7)*3.67%)) -> 458.016 | BN7: =IF(SUM(BE7:BF7)>=15000,1249.5,SUM(BE7:BF7)*8.33%) -> 1039.584 | BO7: =IF(BJ7>=21000,0,BJ7*3.25%) -> 586.43 | BP7: =IF(BJ7>25000,200,IF(BJ7>20000,150,IF(BJ7>15000,100,0))) -> 100 | BQ7: =IF((BJ7*12)<=400000,0, IF((BJ7*12)<=800000,((BJ7*12)-400000)*5%, IF((BJ7*12)<=1200000,20000+((BJ7*12)-800000)*10%, IF((BJ7*12)<=1600000,60000+((BJ7*12)-1200000)*15%, IF((BJ7*12)<=2000000,120000+((BJ7*12)-1600000)*20%, IF((BJ7*12)<=2400000,200000+((BJ7*12)-2000000)*25%, IF((BJ7*12)>2400000,300000+((BJ7*12)-2400000)*30%)))))))/12 -> 0 | BR7: 0 | BS7: =BJ7-BK7-BL7-BP7-BQ7-BR7 -> 16311.07
A8: E00006 | B8: Raj Gupta | C8: MIS Executive | D8: Admin | E8: 9536962915 | F8: 264814525805 | G8: 4495860965 | H8: 3946586353 | I8: 4495860965 | J8: 7767690099 | K8: UFDWO3434U | L8: 558379283425 | M8: 09/176, Ramanathan, Srikakulam 056440 | N8: Ajmer | O8: 299503 | P8: 42676 | Q8: Night | R8: aradhyasalvi@rana-korpal.com | S8: =VLOOKUP($A8&S$2,Sheet2!$D$1:$F$601,3,0) -> P | T8: =VLOOKUP($A8&T$2,Sheet2!$D$1:$F$601,3,0) -> A | U8: =VLOOKUP($A8&U$2,Sheet2!$D$1:$F$601,3,0) -> P | V8: =VLOOKUP($A8&V$2,Sheet2!$D$1:$F$601,3,0) -> P | W8: =VLOOKUP($A8&W$2,Sheet2!$D$1:$F$601,3,0) -> P | X8: =VLOOKUP($A8&X$2,Sheet2!$D$1:$F$601,3,0) -> L | Y8: WO | Z8: =VLOOKUP($A8&Z$2,Sheet2!$D$1:$F$601,3,0) -> P | AA8: =VLOOKUP($A8&AA$2,Sheet2!$D$1:$F$601,3,0) -> P | AB8: =VLOOKUP($A8&AB$2,Sheet2!$D$1:$F$601,3,0) -> P | AC8: =VLOOKUP($A8&AC$2,Sheet2!$D$1:$F$601,3,0) -> P | AD8: =VLOOKUP($A8&AD$2,Sheet2!$D$1:$F$601,3,0) -> P | AE8: =VLOOKUP($A8&AE$2,Sheet2!$D$1:$F$601,3,0) -> A | AF8: WO | AG8: =VLOOKUP($A8&AG$2,Sheet2!$D$1:$F$601,3,0) -> P | AH8: =VLOOKUP($A8&AH$2,Sheet2!$D$1:$F$601,3,0) -> P | AI8: =VLOOKUP($A8&AI$2,Sheet2!$D$1:$F$601,3,0) -> P | AJ8: =VLOOKUP($A8&AJ$2,Sheet2!$D$1:$F$601,3,0) -> A | AK8: =VLOOKUP($A8&AK$2,Sheet2!$D$1:$F$601,3,0) -> P | AL8: =VLOOKUP($A8&AL$2,Sheet2!$D$1:$F$601,3,0) -> P | AM8: WO | AN8: =VLOOKUP($A8&AN$2,Sheet2!$D$1:$F$601,3,0) -> P | AO8: =VLOOKUP($A8&AO$2,Sheet2!$D$1:$F$601,3,0) -> P | AP8: =VLOOKUP($A8&AP$2,Sheet2!$D$1:$F$601,3,0) -> P | AQ8: =VLOOKUP($A8&AQ$2,Sheet2!$D$1:$F$601,3,0) -> P | AR8: =VLOOKUP($A8&AR$2,Sheet2!$D$1:$F$601,3,0) -> A | AS8: =VLOOKUP($A8&AS$2,Sheet2!$D$1:$F$601,3,0) -> P | AT8: WO | AU8: =VLOOKUP($A8&AU$2,Sheet2!$D$1:$F$601,3,0) -> P | AV8: =VLOOKUP($A8&AV$2,Sheet2!$D$1:$F$601,3,0) -> P | AW8: =COUNTIF(S8:AV8,"P") -> 21 | AX8: =COUNTIF(S8:AV8,"A") -> 4 | AY8: =COUNTIF(S8:AV8,"H") -> 0 | AZ8: =COUNTIF(S8:AV8,"L") -> 1 | BA8: =COUNTIF(S8:AV8,"WO") -> 4 | BB8: =COUNTIF(S8:AV8,"HO") -> 0 | BC8: =SUM(AW8:BB8)-AX8-IF(AZ8>1,AZ8-1,0)-(AY8/2) -> 26 | BD8: 14000 | BE8: =BD8/30*BC8 -> 12133.333 | BF8: =BE8*20% -> 2426.6667 | BG8: =BE8*40% -> 4853.3333 | BH8: 2957 | BI8: =VLOOKUP(A8,Sheet3!$A$1:$E$21,5,0) -> 5092 | BJ8: =SUM(BE8:BI8) -> 27462.333 | BK8: =IF(SUM(BE8:BF8)>=15000,1800,(SUM(BE8:BF8)*12%)) -> 1747.2 | BL8: =IF(BJ8>21000,0,BJ8*0.75%) -> 0 | BM8: =IF(SUM(BE8:BF8)>=15000,550.5,(SUM(BE8:BF8)*3.67%)) -> 534.352 | BN8: =IF(SUM(BE8:BF8)>=15000,1249.5,SUM(BE8:BF8)*8.33%) -> 1212.848 | BO8: =IF(BJ8>=21000,0,BJ8*3.25%) -> 0 | BP8: =IF(BJ8>25000,200,IF(BJ8>20000,150,IF(BJ8>15000,100,0))) -> 200 | BQ8: =IF((BJ8*12)<=400000,0, IF((BJ8*12)<=800000,((BJ8*12)-400000)*5%, IF((BJ8*12)<=1200000,20000+((BJ8*12)-800000)*10%, IF((BJ8*12)<=1600000,60000+((BJ8*12)-1200000)*15%, IF((BJ8*12)<=2000000,120000+((BJ8*12)-1600000)*20%, IF((BJ8*12)<=2400000,200000+((BJ8*12)-2000000)*25%, IF((BJ8*12)>2400000,300000+((BJ8*12)-2400000)*30%)))))))/12 -> 0 | BR8: 0 | BS8: =BJ8-BK8-BL8-BP8-BQ8-BR8 -> 25515.133
A9: E00007 | B9: Arjun Reddy | C9: Manager | D9: Admin | E9: 4927993180 | F9: 866531392409 | G9: 1521707674 | H9: 2655515153 | I9: 1521707674 | J9: 6500860399 | K9: OENJW3786B | L9: 106115846466 | M9: 35/996, Rattan Path, Baranagar 245477 | N9: Pimpri-Chinchwad | O9: 367811 | P9: 42498 | Q9: Day | R9: sidhutrisha@jain.org | S9: =VLOOKUP($A9&S$2,Sheet2!$D$1:$F$601,3,0) -> L | T9: =VLOOKUP($A9&T$2,Sheet2!$D$1:$F$601,3,0) -> L | U9: =VLOOKUP($A9&U$2,Sheet2!$D$1:$F$601,3,0) -> P | V9: =VLOOKUP($A9&V$2,Sheet2!$D$1:$F$601,3,0) -> P | W9: =VLOOKUP($A9&W$2,Sheet2!$D$1:$F$601,3,0) -> P | X9: =VLOOKUP($A9&X$2,Sheet2!$D$1:$F$601,3,0) -> P | Y9: WO | Z9: =VLOOKUP($A9&Z$2,Sheet2!$D$1:$F$601,3,0) -> P | AA9: =VLOOKUP($A9&AA$2,Sheet2!$D$1:$F$601,3,0) -> L | AB9: =VLOOKUP($A9&AB$2,Sheet2!$D$1:$F$601,3,0) -> L | AC9: =VLOOKUP($A9&AC$2,Sheet2!$D$1:$F$601,3,0) -> P | AD9: =VLOOKUP($A9&AD$2,Sheet2!$D$1:$F$601,3,0) -> P | AE9: =VLOOKUP($A9&AE$2,Sheet2!$D$1:$F$601,3,0) -> L | AF9: WO | AG9: =VLOOKUP($A9&AG$2,Sheet2!$D$1:$F$601,3,0) -> L | AH9: =VLOOKUP($A9&AH$2,Sheet2!$D$1:$F$601,3,0) -> P | AI9: =VLOOKUP($A9&AI$2,Sheet2!$D$1:$F$601,3,0) -> P | AJ9: =VLOOKUP($A9&AJ$2,Sheet2!$D$1:$F$601,3,0) -> P | AK9: =VLOOKUP($A9&AK$2,Sheet2!$D$1:$F$601,3,0) -> P | AL9: =VLOOKUP($A9&AL$2,Sheet2!$D$1:$F$601,3,0) -> P | AM9: WO | AN9: =VLOOKUP($A9&AN$2,Sheet2!$D$1:$F$601,3,0) -> P | AO9: =VLOOKUP($A9&AO$2,Sheet2!$D$1:$F$601,3,0) -> P | AP9: =VLOOKUP($A9&AP$2,Sheet2!$D$1:$F$601,3,0) -> P | AQ9: =VLOOKUP($A9&AQ$2,Sheet2!$D$1:$F$601,3,0) -> L | AR9: =VLOOKUP($A9&AR$2,Sheet2!$D$1:$F$601,3,0) -> P | AS9: =VLOOKUP($A9&AS$2,Sheet2!$D$1:$F$601,3,0) -> P | AT9: WO | AU9: =VLOOKUP($A9&AU$2,Sheet2!$D$1:$F$601,3,0) -> L | AV9: =VLOOKUP($A9&AV$2,Sheet2!$D$1:$F$601,3,0) -> P | AW9: =COUNTIF(S9:AV9,"P") -> 18 | AX9: =COUNTIF(S9:AV9,"A") -> 0 | AY9: =COUNTIF(S9:AV9,"H") -> 0 | AZ9: =COUNTIF(S9:AV9,"L") -> 8 | BA9: =COUNTIF(S9:AV9,"WO") -> 4 | BB9: =COUNTIF(S9:AV9,"HO") -> 0 | BC9: =SUM(AW9:BB9)-AX9-IF(AZ9>1,AZ9-1,0)-(AY9/2) -> 23 | BD9: 14000 | BE9: =BD9/30*BC9 -> 10733.333 | BF9: =BE9*20% -> 2146.6667 | BG9: =BE9*40% -> 4293.3333 | BH9: 1687 | BI9: =VLOOKUP(A9,Sheet3!$A$1:$E$21,5,0) -> 0 | BJ9: =SUM(BE9:BI9) -> 18860.333 | BK9: =IF(SUM(BE9:BF9)>=15000,1800,(SUM(BE9:BF9)*12%)) -> 1545.6 | BL9: =IF(BJ9>21000,0,BJ9*0.75%) -> 141.4525 | BM9: =IF(SUM(BE9:BF9)>=15000,550.5,(SUM(BE9:BF9)*3.67%)) -> 472.696 | BN9: =IF(SUM(BE9:BF9)>=15000,1249.5,SUM(BE9:BF9)*8.33%) -> 1072.904 | BO9: =IF(BJ9>=21000,0,BJ9*3.25%) -> 612.96083 | BP9: =IF(BJ9>25000,200,IF(BJ9>20000,150,IF(BJ9>15000,100,0))) -> 100 | BQ9: =IF((BJ9*12)<=400000,0, IF((BJ9*12)<=800000,((BJ9*12)-400000)*5%, IF((BJ9*12)<=1200000,20000+((BJ9*12)-800000)*10%, IF((BJ9*12)<=1600000,60000+((BJ9*12)-1200000)*15%, IF((BJ9*12)<=2000000,120000+((BJ9*12)-1600000)*20%, IF((BJ9*12)<=2400000,200000+((BJ9*12)-2000000)*25%, IF((BJ9*12)>2400000,300000+((BJ9*12)-2400000)*30%)))))))/12 -> 0 | BR9: 0 | BS9: =BJ9-BK9-BL9-BP9-BQ9-BR9 -> 17073.281
A10: E00008 | B10: Amit Rao | C10: Officer | D10: HR | E10: 6397442982 | F10: 968194229213 | G10: 5793510605 | H10: 8480553257 | I10: 5793510605 | J10: 4009807929 | K10: ZEGKG8218G | L10: 570980210728 | M10: H.No. 573, Doctor Marg, Anand-441446 | N10: Haridwar | O10: 108765 | P10: 44730 | Q10: Day | R10: jiyahayre@yahoo.com | S10: =VLOOKUP($A10&S$2,Sheet2!$D$1:$F$601,3,0) -> P | T10: =VLOOKUP($A10&T$2,Sheet2!$D$1:$F$601,3,0) -> P | U10: =VLOOKUP($A10&U$2,Sheet2!$D$1:$F$601,3,0) -> P | V10: =VLOOKUP($A10&V$2,Sheet2!$D$1:$F$601,3,0) -> P | W10: =VLOOKUP($A10&W$2,Sheet2!$D$1:$F$601,3,0) -> L | X10: =VLOOKUP($A10&X$2,Sheet2!$D$1:$F$601,3,0) -> P | Y10: WO | Z10: =VLOOKUP($A10&Z$2,Sheet2!$D$1:$F$601,3,0) -> P | AA10: =VLOOKUP($A10&AA$2,Sheet2!$D$1:$F$601,3,0) -> P | AB10: =VLOOKUP($A10&AB$2,Sheet2!$D$1:$F$601,3,0) -> P | AC10: =VLOOKUP($A10&AC$2,Sheet2!$D$1:$F$601,3,0) -> P | AD10: =VLOOKUP($A10&AD$2,Sheet2!$D$1:$F$601,3,0) -> A | AE10: =VLOOKUP($A10&AE$2,Sheet2!$D$1:$F$601,3,0) -> A | AF10: WO | AG10: =VLOOKUP($A10&AG$2,Sheet2!$D$1:$F$601,3,0) -> P | AH10: =VLOOKUP($A10&AH$2,Sheet2!$D$1:$F$601,3,0) -> P | AI10: =VLOOKUP($A10&AI$2,Sheet2!$D$1:$F$601,3,0) -> A | AJ10: =VLOOKUP($A10&AJ$2,Sheet2!$D$1:$F$601,3,0) -> P | AK10: =VLOOKUP($A10&AK$2,Sheet2!$D$1:$F$601,3,0) -> L | AL10: =VLOOKUP($A10&AL$2,Sheet2!$D$1:$F$601,3,0) -> P | AM10: WO | AN10: =VLOOKUP($A10&AN$2,Sheet2!$D$1:$F$601,3,0) -> P | AO10: =VLOOKUP($A10&AO$2,Sheet2!$D$1:$F$601,3,0) -> L | AP10: =VLOOKUP($A10&AP$2,Sheet2!$D$1:$F$601,3,0) -> P | AQ10: =VLOOKUP($A10&AQ$2,Sheet2!$D$1:$F$601,3,0) -> A | AR10: =VLOOKUP($A10&AR$2,Sheet2!$D$1:$F$601,3,0) -> P | AS10: =VLOOKUP($A10&AS$2,Sheet2!$D$1:$F$601,3,0) -> P | AT10: WO | AU10: =VLOOKUP($A10&AU$2,Sheet2!$D$1:$F$601,3,0) -> P | AV10: =VLOOKUP($A10&AV$2,Sheet2!$D$1:$F$601,3,0) -> P | AW10: =COUNTIF(S10:AV10,"P") -> 19 | AX10: =COUNTIF(S10:AV10,"A") -> 4 | AY10: =COUNTIF(S10:AV10,"H") -> 0 | AZ10: =COUNTIF(S10:AV10,"L") -> 3 | BA10: =COUNTIF(S10:AV10,"WO") -> 4 | BB10: =COUNTIF(S10:AV10,"HO") -> 0 | BC10: =SUM(AW10:BB10)-AX10-IF(AZ10>1,AZ10-1,0)-(AY10/2) -> 24 | BD10: 15000 | BE10: =BD10/30*BC10 -> 12000 | BF10: =BE10*20% -> 2400 | BG10: =BE10*40% -> 4800 | BH10: 2740 | BI10: =VLOOKUP(A10,Sheet3!$A$1:$E$21,5,0) -> 0 | BJ10: =SUM(BE10:BI10) -> 21940 | BK10: =IF(SUM(BE10:BF10)>=15000,1800,(SUM(BE10:BF10)*12%)) -> 1728 | BL10: =IF(BJ10>21000,0,BJ10*0.75%) -> 0 | BM10: =IF(SUM(BE10:BF10)>=15000,550.5,(SUM(BE10:BF10)*3.67%)) -> 528.48 | BN10: =IF(SUM(BE10:BF10)>=15000,1249.5,SUM(BE10:BF10)*8.33%) -> 1199.52 | BO10: =IF(BJ10>=21000,0,BJ10*3.25%) -> 0 | BP10: =IF(BJ10>25000,200,IF(BJ10>20000,150,IF(BJ10>15000,100,0))) -> 150 | BQ10: =IF((BJ10*12)<=400000,0, IF((BJ10*12)<=800000,((BJ10*12)-400000)*5%, IF((BJ10*12)<=1200000,20000+((BJ10*12)-800000)*10%, IF((BJ10*12)<=1600000,60000+((BJ10*12)-1200000)*15%, IF((BJ10*12)<=2000000,120000+((BJ10*12)-1600000)*20%, IF((BJ10*12)<=2400000,200000+((BJ10*12)-2000000)*25%, IF((BJ10*12)>2400000,300000+((BJ10*12)-2400000)*30%)))))))/12 -> 0 | BR10: 2000 | BS10: =BJ10-BK10-BL10-BP10-BQ10-BR10 -> 18062
A11: E00009 | B11: Rohit Mehta | C11: Supervisor | D11: MIS | E11: 5634207864 | F11: 535246406726 | G11: 5418940820 | H11: 2769236176 | I11: 5418940820 | J11: 7471568060 | K11: NNTAL6748Q | L11: 948971962006 | M11: H.No. 92, Mammen, Kirari Suleman Nagar 295910 | N11: Tezpur | O11: 929078 | P11: 45763 | Q11: Day | R11: irachatterjee@hotmail.com | S11: =VLOOKUP($A11&S$2,Sheet2!$D$1:$F$601,3,0) -> P | T11: =VLOOKUP($A11&T$2,Sheet2!$D$1:$F$601,3,0) -> P | U11: =VLOOKUP($A11&U$2,Sheet2!$D$1:$F$601,3,0) -> P | V11: =VLOOKUP($A11&V$2,Sheet2!$D$1:$F$601,3,0) -> P | W11: =VLOOKUP($A11&W$2,Sheet2!$D$1:$F$601,3,0) -> P | X11: =VLOOKUP($A11&X$2,Sheet2!$D$1:$F$601,3,0) -> A | Y11: WO | Z11: =VLOOKUP($A11&Z$2,Sheet2!$D$1:$F$601,3,0) -> L | AA11: =VLOOKUP($A11&AA$2,Sheet2!$D$1:$F$601,3,0) -> A | AB11: =VLOOKUP($A11&AB$2,Sheet2!$D$1:$F$601,3,0) -> P | AC11: =VLOOKUP($A11&AC$2,Sheet2!$D$1:$F$601,3,0) -> P | AD11: =VLOOKUP($A11&AD$2,Sheet2!$D$1:$F$601,3,0) -> P | AE11: =VLOOKUP($A11&AE$2,Sheet2!$D$1:$F$601,3,0) -> P | AF11: WO | AG11: =VLOOKUP($A11&AG$2,Sheet2!$D$1:$F$601,3,0) -> P | AH11: =VLOOKUP($A11&AH$2,Sheet2!$D$1:$F$601,3,0) -> P | AI11: =VLOOKUP($A11&AI$2,Sheet2!$D$1:$F$601,3,0) -> L | AJ11: =VLOOKUP($A11&AJ$2,Sheet2!$D$1:$F$601,3,0) -> P | AK11: =VLOOKUP($A11&AK$2,Sheet2!$D$1:$F$601,3,0) -> P | AL11: =VLOOKUP($A11&AL$2,Sheet2!$D$1:$F$601,3,0) -> A | AM11: WO | AN11: =VLOOKUP($A11&AN$2,Sheet2!$D$1:$F$601,3,0) -> P | AO11: =VLOOKUP($A11&AO$2,Sheet2!$D$1:$F$601,3,0) -> P | AP11: =VLOOKUP($A11&AP$2,Sheet2!$D$1:$F$601,3,0) -> P | AQ11: =VLOOKUP($A11&AQ$2,Sheet2!$D$1:$F$601,3,0) -> P | AR11: =VLOOKUP($A11&AR$2,Sheet2!$D$1:$F$601,3,0) -> P | AS11: =VLOOKUP($A11&AS$2,Sheet2!$D$1:$F$601,3,0) -> P | AT11: WO | AU11: =VLOOKUP($A11&AU$2,Sheet2!$D$1:$F$601,3,0) -> L | AV11: =VLOOKUP($A11&AV$2,Sheet2!$D$1:$F$601,3,0) -> P | AW11: =COUNTIF(S11:AV11,"P") -> 20 | AX11: =COUNTIF(S11:AV11,"A") -> 3 | AY11: =COUNTIF(S11:AV11,"H") -> 0 | AZ11: =COUNTIF(S11:AV11,"L") -> 3 | BA11: =COUNTIF(S11:AV11,"WO") -> 4 | BB11: =COUNTIF(S11:AV11,"HO") -> 0 | BC11: =SUM(AW11:BB11)-AX11-IF(AZ11>1,AZ11-1,0)-(AY11/2) -> 25 | BD11: 16000 | BE11: =BD11/30*BC11 -> 13333.333 | BF11: =BE11*20% -> 2666.6667 | BG11: =BE11*40% -> 5333.3333 | BH11: 1434 | BI11: =VLOOKUP(A11,Sheet3!$A$1:$E$21,5,0) -> 5690.45 | BJ11: =SUM(BE11:BI11) -> 28457.783 | BK11: =IF(SUM(BE11:BF11)>=15000,1800,(SUM(BE11:BF11)*12%)) -> 1800 | BL11: =IF(BJ11>21000,0,BJ11*0.75%) -> 0 | BM11: =IF(SUM(BE11:BF11)>=15000,550.5,(SUM(BE11:BF11)*3.67%)) -> 550.5 | BN11: =IF(SUM(BE11:BF11)>=15000,1249.5,SUM(BE11:BF11)*8.33%) -> 1249.5 | BO11: =IF(BJ11>=21000,0,BJ11*3.25%) -> 0 | BP11: =IF(BJ11>25000,200,IF(BJ11>20000,150,IF(BJ11>15000,100,0))) -> 200 | BQ11: =IF((BJ11*12)<=400000,0, IF((BJ11*12)<=800000,((BJ11*12)-400000)*5%, IF((BJ11*12)<=1200000,20000+((BJ11*12)-800000)*10%, IF((BJ11*12)<=1600000,60000+((BJ11*12)-1200000)*15%, IF((BJ11*12)<=2000000,120000+((BJ11*12)-1600000)*20%, IF((BJ11*12)<=2400000,200000+((BJ11*12)-2000000)*25%, IF((BJ11*12)>2400000,300000+((BJ11*12)-2400000)*30%)))))))/12 -> 0 | BR11: 0 | BS11: =BJ11-BK11-BL11-BP11-BQ11-BR11 -> 26457.783
A12: E00010 | B12: Suresh Kapoor | C12: Officer | D12: Admin | E12: 3503836965 | F12: 203135355315 | G12: 3738087416 | H12: 9081144879 | I12: 3738087416 | J12: 9437660696 | K12: CXJHA2866K | L12: 158139048082 | M12: 97, Sastry Path, Begusarai 985792 | N12: Vellore | O12: 879330 | P12: 42296 | Q12: Night | R12: shaanmani@hotmail.com | S12: =VLOOKUP($A12&S$2,Sheet2!$D$1:$F$601,3,0) -> A | T12: =VLOOKUP($A12&T$2,Sheet2!$D$1:$F$601,3,0) -> P | U12: =VLOOKUP($A12&U$2,Sheet2!$D$1:$F$601,3,0) -> A | V12: =VLOOKUP($A12&V$2,Sheet2!$D$1:$F$601,3,0) -> P | W12: =VLOOKUP($A12&W$2,Sheet2!$D$1:$F$601,3,0) -> L | X12: =VLOOKUP($A12&X$2,Sheet2!$D$1:$F$601,3,0) -> A | Y12: WO | Z12: =VLOOKUP($A12&Z$2,Sheet2!$D$1:$F$601,3,0) -> P | AA12: =VLOOKUP($A12&AA$2,Sheet2!$D$1:$F$601,3,0) -> P | AB12: =VLOOKUP($A12&AB$2,Sheet2!$D$1:$F$601,3,0) -> P | AC12: =VLOOKUP($A12&AC$2,Sheet2!$D$1:$F$601,3,0) -> P | AD12: =VLOOKUP($A12&AD$2,Sheet2!$D$1:$F$601,3,0) -> P | AE12: =VLOOKUP($A12&AE$2,Sheet2!$D$1:$F$601,3,0) -> P | AF12: WO | AG12: =VLOOKUP($A12&AG$2,Sheet2!$D$1:$F$601,3,0) -> L | AH12: =VLOOKUP($A12&AH$2,Sheet2!$D$1:$F$601,3,0) -> P | AI12: =VLOOKUP($A12&AI$2,Sheet2!$D$1:$F$601,3,0) -> L | AJ12: =VLOOKUP($A12&AJ$2,Sheet2!$D$1:$F$601,3,0) -> P | AK12: =VLOOKUP($A12&AK$2,Sheet2!$D$1:$F$601,3,0) -> P | AL12: =VLOOKUP($A12&AL$2,Sheet2!$D$1:$F$601,3,0) -> P | AM12: WO | AN12: =VLOOKUP($A12&AN$2,Sheet2!$D$1:$F$601,3,0) -> A | AO12: =VLOOKUP($A12&AO$2,Sheet2!$D$1:$F$601,3,0) -> P | AP12: =VLOOKUP($A12&AP$2,Sheet2!$D$1:$F$601,3,0) -> P | AQ12: =VLOOKUP($A12&AQ$2,Sheet2!$D$1:$F$601,3,0) -> P | AR12: =VLOOKUP($A12&AR$2,Sheet2!$D$1:$F$601,3,0) -> P | AS12: =VLOOKUP($A12&AS$2,Sheet2!$D$1:$F$601,3,0) -> P | AT12: WO | AU12: =VLOOKUP($A12&AU$2,Sheet2!$D$1:$F$601,3,0) -> L | AV12: =VLOOKUP($A12&AV$2,Sheet2!$D$1:$F$601,3,0) -> P | AW12: =COUNTIF(S12:AV12,"P") -> 18 | AX12: =COUNTIF(S12:AV12,"A") -> 4 | AY12: =COUNTIF(S12:AV12,"H") -> 0 | AZ12: =COUNTIF(S12:AV12,"L") -> 4 | BA12: =COUNTIF(S12:AV12,"WO") -> 4 | BB12: =COUNTIF(S12:AV12,"HO") -> 0 | BC12: =SUM(AW12:BB12)-AX12-IF(AZ12>1,AZ12-1,0)-(AY12/2) -> 23 | BD12: 13000 | BE12: =BD12/30*BC12 -> 9966.6667 | BF12: =BE12*20% -> 1993.3333 | BG12: =BE12*40% -> 3986.6667 | BH12: 2175 | BI12: =VLOOKUP(A12,Sheet3!$A$1:$E$21,5,0) -> 0 | BJ12: =SUM(BE12:BI12) -> 18121.667 | BK12: =IF(SUM(BE12:BF12)>=15000,1800,(SUM(BE12:BF12)*12%)) -> 1435.2 | BL12: =IF(BJ12>21000,0,BJ12*0.75%) -> 135.9125 | BM12: =IF(SUM(BE12:BF12)>=15000,550.5,(SUM(BE12:BF12)*3.67%)) -> 438.932 | BN12: =IF(SUM(BE12:BF12)>=15000,1249.5,SUM(BE12:BF12)*8.33%) -> 996.268 | BO12: =IF(BJ12>=21000,0,BJ12*3.25%) -> 588.95417 | BP12: =IF(BJ12>25000,200,IF(BJ12>20000,150,IF(BJ12>15000,100,0))) -> 100 | BQ12: =IF((BJ12*12)<=400000,0, IF((BJ12*12)<=800000,((BJ12*12)-400000)*5%, IF((BJ12*12)<=1200000,20000+((BJ12*12)-800000)*10%, IF((BJ12*12)<=1600000,60000+((BJ12*12)-1200000)*15%, IF((BJ12*12)<=2000000,120000+((BJ12*12)-1600000)*20%, IF((BJ12*12)<=2400000,200000+((BJ12*12)-2000000)*25%, IF((BJ12*12)>2400000,300000+((BJ12*12)-2400000)*30%)))))))/12 -> 0 | BR12: 0 | BS12: =BJ12-BK12-BL12-BP12-BQ12-BR12 -> 16450.554
A13: E00011 | B13: Vijay Jain | C13: Executive | D13: MIS | E13: 7296665345 | F13: 560997924220 | G13: 6441833398 | H13: 1646095808 | I13: 6441833398 | J13: 9081567387 | K13: IOYYY3750J | L13: 722672822348 | M13: 02/90, Dey Zila, Madurai-475018 | N13: Suryapet | O13: 128288 | P13: 44656 | Q13: Night | R13: stuvan05@bhatia.com | S13: =VLOOKUP($A13&S$2,Sheet2!$D$1:$F$601,3,0) -> P | T13: =VLOOKUP($A13&T$2,Sheet2!$D$1:$F$601,3,0) -> P | U13: =VLOOKUP($A13&U$2,Sheet2!$D$1:$F$601,3,0) -> P | V13: =VLOOKUP($A13&V$2,Sheet2!$D$1:$F$601,3,0) -> P | W13: =VLOOKUP($A13&W$2,Sheet2!$D$1:$F$601,3,0) -> P | X13: =VLOOKUP($A13&X$2,Sheet2!$D$1:$F$601,3,0) -> L | Y13: WO | Z13: =VLOOKUP($A13&Z$2,Sheet2!$D$1:$F$601,3,0) -> P | AA13: =VLOOKUP($A13&AA$2,Sheet2!$D$1:$F$601,3,0) -> P | AB13: =VLOOKUP($A13&AB$2,Sheet2!$D$1:$F$601,3,0) -> P | AC13: =VLOOKUP($A13&AC$2,Sheet2!$D$1:$F$601,3,0) -> L | AD13: =VLOOKUP($A13&AD$2,Sheet2!$D$1:$F$601,3,0) -> P | AE13: =VLOOKUP($A13&AE$2,Sheet2!$D$1:$F$601,3,0) -> P | AF13: WO | AG13: =VLOOKUP($A13&AG$2,Sheet2!$D$1:$F$601,3,0) -> A | AH13: =VLOOKUP($A13&AH$2,Sheet2!$D$1:$F$601,3,0) -> P | AI13: =VLOOKUP($A13&AI$2,Sheet2!$D$1:$F$601,3,0) -> P | AJ13: =VLOOKUP($A13&AJ$2,Sheet2!$D$1:$F$601,3,0) -> P | AK13: =VLOOKUP($A13&AK$2,Sheet2!$D$1:$F$601,3,0) -> P | AL13: =VLOOKUP($A13&AL$2,Sheet2!$D$1:$F$601,3,0) -> A | AM13: WO | AN13: =VLOOKUP($A13&AN$2,Sheet2!$D$1:$F$601,3,0) -> P | AO13: =VLOOKUP($A13&AO$2,Sheet2!$D$1:$F$601,3,0) -> L | AP13: =VLOOKUP($A13&AP$2,Sheet2!$D$1:$F$601,3,0) -> P | AQ13: =VLOOKUP($A13&AQ$2,Sheet2!$D$1:$F$601,3,0) -> P | AR13: =VLOOKUP($A13&AR$2,Sheet2!$D$1:$F$601,3,0) -> L | AS13: =VLOOKUP($A13&AS$2,Sheet2!$D$1:$F$601,3,0) -> P | AT13: WO | AU13: =VLOOKUP($A13&AU$2,Sheet2!$D$1:$F$601,3,0) -> P | AV13: =VLOOKUP($A13&AV$2,Sheet2!$D$1:$F$601,3,0) -> P | AW13: =COUNTIF(S13:AV13,"P") -> 20 | AX13: =COUNTIF(S13:AV13,"A") -> 2 | AY13: =COUNTIF(S13:AV13,"H") -> 0 | AZ13: =COUNTIF(S13:AV13,"L") -> 4 | BA13: =COUNTIF(S13:AV13,"WO") -> 4 | BB13: =COUNTIF(S13:AV13,"HO") -> 0 | BC13: =SUM(AW13:BB13)-AX13-IF(AZ13>1,AZ13-1,0)-(AY13/2) -> 25 | BD13: 16000 | BE13: =BD13/30*BC13 -> 13333.333 | BF13: =BE13*20% -> 2666.6667 | BG13: =BE13*40% -> 5333.3333 | BH13: 1074 | BI13: =VLOOKUP(A13,Sheet3!$A$1:$E$21,5,0) -> 0 | BJ13: =SUM(BE13:BI13) -> 22407.333 | BK13: =IF(SUM(BE13:BF13)>=15000,1800,(SUM(BE13:BF13)*12%)) -> 1800 | BL13: =IF(BJ13>21000,0,BJ13*0.75%) -> 0 | BM13: =IF(SUM(BE13:BF13)>=15000,550.5,(SUM(BE13:BF13)*3.67%)) -> 550.5 | BN13: =IF(SUM(BE13:BF13)>=15000,1249.5,SUM(BE13:BF13)*8.33%) -> 1249.5 | BO13: =IF(BJ13>=21000,0,BJ13*3.25%) -> 0 | BP13: =IF(BJ13>25000,200,IF(BJ13>20000,150,IF(BJ13>15000,100,0))) -> 150 | BQ13: =IF((BJ13*12)<=400000,0, IF((BJ13*12)<=800000,((BJ13*12)-400000)*5%, IF((BJ13*12)<=1200000,20000+((BJ13*12)-800000)*10%, IF((BJ13*12)<=1600000,60000+((BJ13*12)-1200000)*15%, IF((BJ13*12)<=2000000,120000+((BJ13*12)-1600000)*20%, IF((BJ13*12)<=2400000,200000+((BJ13*12)-2000000)*25%, IF((BJ13*12)>2400000,300000+((BJ13*12)-2400000)*30%)))))))/12 -> 0 | BR13: 0 | BS13: =BJ13-BK13-BL13-BP13-BQ13-BR13 -> 20457.333
A14: E00012 | B14: Raj Khan | C14: Admin | D14: Sales | E14: 4546856423 | F14: 564959942032 | G14: 1323632199 | H14: 5566859975 | I14: 1323632199 | J14: 2379588259 | K14: KMXZZ9299V | L14: 169600867832 | M14: H.No. 869, Sem Nagar, Bhiwandi 457425 | N14: Bijapur | O14: 477271 | P14: 43655 | Q14: Night | R14: tanyabhargava@bhattacharyya-chokshi.info | S14: =VLOOKUP($A14&S$2,Sheet2!$D$1:$F$601,3,0) -> A | T14: =VLOOKUP($A14&T$2,Sheet2!$D$1:$F$601,3,0) -> P | U14: =VLOOKUP($A14&U$2,Sheet2!$D$1:$F$601,3,0) -> P | V14: =VLOOKUP($A14&V$2,Sheet2!$D$1:$F$601,3,0) -> P | W14: =VLOOKUP($A14&W$2,Sheet2!$D$1:$F$601,3,0) -> P | X14: =VLOOKUP($A14&X$2,Sheet2!$D$1:$F$601,3,0) -> P | Y14: WO | Z14: =VLOOKUP($A14&Z$2,Sheet2!$D$1:$F$601,3,0) -> P | AA14: =VLOOKUP($A14&AA$2,Sheet2!$D$1:$F$601,3,0) -> L | AB14: =VLOOKUP($A14&AB$2,Sheet2!$D$1:$F$601,3,0) -> P | AC14: =VLOOKUP($A14&AC$2,Sheet2!$D$1:$F$601,3,0) -> P | AD14: =VLOOKUP($A14&AD$2,Sheet2!$D$1:$F$601,3,0) -> A | AE14: =VLOOKUP($A14&AE$2,Sheet2!$D$1:$F$601,3,0) -> P | AF14: WO | AG14: =VLOOKUP($A14&AG$2,Sheet2!$D$1:$F$601,3,0) -> A | AH14: =VLOOKUP($A14&AH$2,Sheet2!$D$1:$F$601,3,0) -> P | AI14: =VLOOKUP($A14&AI$2,Sheet2!$D$1:$F$601,3,0) -> P | AJ14: =VLOOKUP($A14&AJ$2,Sheet2!$D$1:$F$601,3,0) -> P | AK14: =VLOOKUP($A14&AK$2,Sheet2!$D$1:$F$601,3,0) -> P | AL14: =VLOOKUP($A14&AL$2,Sheet2!$D$1:$F$601,3,0) -> P | AM14: WO | AN14: =VLOOKUP($A14&AN$2,Sheet2!$D$1:$F$601,3,0) -> P | AO14: =VLOOKUP($A14&AO$2,Sheet2!$D$1:$F$601,3,0) -> P | AP14: =VLOOKUP($A14&AP$2,Sheet2!$D$1:$F$601,3,0) -> P | AQ14: =VLOOKUP($A14&AQ$2,Sheet2!$D$1:$F$601,3,0) -> P | AR14: =VLOOKUP($A14&AR$2,Sheet2!$D$1:$F$601,3,0) -> L | AS14: =VLOOKUP($A14&AS$2,Sheet2!$D$1:$F$601,3,0) -> P | AT14: WO | AU14: =VLOOKUP($A14&AU$2,Sheet2!$D$1:$F$601,3,0) -> P | AV14: =VLOOKUP($A14&AV$2,Sheet2!$D$1:$F$601,3,0) -> P | AW14: =COUNTIF(S14:AV14,"P") -> 21 | AX14: =COUNTIF(S14:AV14,"A") -> 3 | AY14: =COUNTIF(S14:AV14,"H") -> 0 | AZ14: =COUNTIF(S14:AV14,"L") -> 2 | BA14: =COUNTIF(S14:AV14,"WO") -> 4 | BB14: =COUNTIF(S14:AV14,"HO") -> 0 | BC14: =SUM(AW14:BB14)-AX14-IF(AZ14>1,AZ14-1,0)-(AY14/2) -> 26 | BD14: 29000 | BE14: =BD14/30*BC14 -> 25133.333 | BF14: =BE14*20% -> 5026.6667 | BG14: =BE14*40% -> 10053.333 | BH14: 1598 | BI14: =VLOOKUP(A14,Sheet3!$A$1:$E$21,5,0) -> 5921.95 | BJ14: =SUM(BE14:BI14) -> 47733.283 | BK14: =IF(SUM(BE14:BF14)>=15000,1800,(SUM(BE14:BF14)*12%)) -> 1800 | BL14: =IF(BJ14>21000,0,BJ14*0.75%) -> 0 | BM14: =IF(SUM(BE14:BF14)>=15000,550.5,(SUM(BE14:BF14)*3.67%)) -> 550.5 | BN14: =IF(SUM(BE14:BF14)>=15000,1249.5,SUM(BE14:BF14)*8.33%) -> 1249.5 | BO14: =IF(BJ14>=21000,0,BJ14*3.25%) -> 0 | BP14: =IF(BJ14>25000,200,IF(BJ14>20000,150,IF(BJ14>15000,100,0))) -> 200 | BQ14: =IF((BJ14*12)<=400000,0, IF((BJ14*12)<=800000,((BJ14*12)-400000)*5%, IF((BJ14*12)<=1200000,20000+((BJ14*12)-800000)*10%, IF((BJ14*12)<=1600000,60000+((BJ14*12)-1200000)*15%, IF((BJ14*12)<=2000000,120000+((BJ14*12)-1600000)*20%, IF((BJ14*12)<=2400000,200000+((BJ14*12)-2000000)*25%, IF((BJ14*12)>2400000,300000+((BJ14*12)-2400000)*30%)))))))/12 -> 719.9975 | BR14: 0 | BS14: =BJ14-BK14-BL14-BP14-BQ14-BR14 -> 45013.286
A15: E00013 | B15: Arjun Kohli | C15: Head | D15: IT | E15: 1364617873 | F15: 436189546308 | G15: 9629726834 | H15: 2933429226 | I15: 9629726834 | J15: 8020564672 | K15: ABHGW8266S | L15: 380313982921 | M15: H.No. 22, Chaudhry Circle, Warangal 359716 | N15: Nanded | O15: 407751 | P15: 42548 | Q15: Night | R15: kalaanahita@gmail.com | S15: =VLOOKUP($A15&S$2,Sheet2!$D$1:$F$601,3,0) -> A | T15: =VLOOKUP($A15&T$2,Sheet2!$D$1:$F$601,3,0) -> L | U15: =VLOOKUP($A15&U$2,Sheet2!$D$1:$F$601,3,0) -> A | V15: =VLOOKUP($A15&V$2,Sheet2!$D$1:$F$601,3,0) -> P | W15: =VLOOKUP($A15&W$2,Sheet2!$D$1:$F$601,3,0) -> P | X15: =VLOOKUP($A15&X$2,Sheet2!$D$1:$F$601,3,0) -> L | Y15: WO | Z15: =VLOOKUP($A15&Z$2,Sheet2!$D$1:$F$601,3,0) -> L | AA15: =VLOOKUP($A15&AA$2,Sheet2!$D$1:$F$601,3,0) -> P | AB15: =VLOOKUP($A15&AB$2,Sheet2!$D$1:$F$601,3,0) -> P | AC15: =VLOOKUP($A15&AC$2,Sheet2!$D$1:$F$601,3,0) -> P | AD15: =VLOOKUP($A15&AD$2,Sheet2!$D$1:$F$601,3,0) -> P | AE15: =VLOOKUP($A15&AE$2,Sheet2!$D$1:$F$601,3,0) -> P | AF15: WO | AG15: =VLOOKUP($A15&AG$2,Sheet2!$D$1:$F$601,3,0) -> L | AH15: =VLOOKUP($A15&AH$2,Sheet2!$D$1:$F$601,3,0) -> L | AI15: =VLOOKUP($A15&AI$2,Sheet2!$D$1:$F$601,3,0) -> P | AJ15: =VLOOKUP($A15&AJ$2,Sheet2!$D$1:$F$601,3,0) -> L | AK15: =VLOOKUP($A15&AK$2,Sheet2!$D$1:$F$601,3,0) -> P | AL15: =VLOOKUP($A15&AL$2,Sheet2!$D$1:$F$601,3,0) -> P | AM15: WO | AN15: =VLOOKUP($A15&AN$2,Sheet2!$D$1:$F$601,3,0) -> P | AO15: =VLOOKUP($A15&AO$2,Sheet2!$D$1:$F$601,3,0) -> P | AP15: =VLOOKUP($A15&AP$2,Sheet2!$D$1:$F$601,3,0) -> P | AQ15: =VLOOKUP($A15&AQ$2,Sheet2!$D$1:$F$601,3,0) -> P | AR15: =VLOOKUP($A15&AR$2,Sheet2!$D$1:$F$601,3,0) -> P | AS15: =VLOOKUP($A15&AS$2,Sheet2!$D$1:$F$601,3,0) -> P | AT15: WO | AU15: =VLOOKUP($A15&AU$2,Sheet2!$D$1:$F$601,3,0) -> P | AV15: =VLOOKUP($A15&AV$2,Sheet2!$D$1:$F$601,3,0) -> P | AW15: =COUNTIF(S15:AV15,"P") -> 18 | AX15: =COUNTIF(S15:AV15,"A") -> 2 | AY15: =COUNTIF(S15:AV15,"H") -> 0 | AZ15: =COUNTIF(S15:AV15,"L") -> 6 | BA15: =COUNTIF(S15:AV15,"WO") -> 4 | BB15: =COUNTIF(S15:AV15,"HO") -> 0 | BC15: =SUM(AW15:BB15)-AX15-IF(AZ15>1,AZ15-1,0)-(AY15/2) -> 23 | BD15: 14000 | BE15: =BD15/30*BC15 -> 10733.333 | BF15: =BE15*20% -> 2146.6667 | BG15: =BE15*40% -> 4293.3333 | BH15: 2222 | BI15: =VLOOKUP(A15,Sheet3!$A$1:$E$21,5,0) -> 5976.05 | BJ15: =SUM(BE15:BI15) -> 25371.383 | BK15: =IF(SUM(BE15:BF15)>=15000,1800,(SUM(BE15:BF15)*12%)) -> 1545.6 | BL15: =IF(BJ15>21000,0,BJ15*0.75%) -> 0 | BM15: =IF(SUM(BE15:BF15)>=15000,550.5,(SUM(BE15:BF15)*3.67%)) -> 472.696 | BN15: =IF(SUM(BE15:BF15)>=15000,1249.5,SUM(BE15:BF15)*8.33%) -> 1072.904 | BO15: =IF(BJ15>=21000,0,BJ15*3.25%) -> 0 | BP15: =IF(BJ15>25000,200,IF(BJ15>20000,150,IF(BJ15>15000,100,0))) -> 200 | BQ15: =IF((BJ15*12)<=400000,0, IF((BJ15*12)<=800000,((BJ15*12)-400000)*5%, IF((BJ15*12)<=1200000,20000+((BJ15*12)-800000)*10%, IF((BJ15*12)<=1600000,60000+((BJ15*12)-1200000)*15%, IF((BJ15*12)<=2000000,120000+((BJ15*12)-1600000)*20%, IF((BJ15*12)<=2400000,200000+((BJ15*12)-2000000)*25%, IF((BJ15*12)>2400000,300000+((BJ15*12)-2400000)*30%)))))))/12 -> 0 | BR15: 0 | BS15: =BJ15-BK15-BL15-BP15-BQ15-BR15 -> 23625.783
A16: E00014 | B16: Amit Nair | C16: Head | D16: Sales | E16: 2493143900 | F16: 270488639929 | G16: 6575979860 | H16: 4090424833 | I16: 6575979860 | J16: 7399256583 | K16: WWGSX9723W | L16: 932182598792 | M16: H.No. 80, Ram Nagar, Moradabad 141310 | N16: Patna | O16: 319348 | P16: 45108 | Q16: Day | R16: bajwariaan@yahoo.com | S16: =VLOOKUP($A16&S$2,Sheet2!$D$1:$F$601,3,0) -> P | T16: =VLOOKUP($A16&T$2,Sheet2!$D$1:$F$601,3,0) -> P | U16: =VLOOKUP($A16&U$2,Sheet2!$D$1:$F$601,3,0) -> P | V16: =VLOOKUP($A16&V$2,Sheet2!$D$1:$F$601,3,0) -> L | W16: =VLOOKUP($A16&W$2,Sheet2!$D$1:$F$601,3,0) -> P | X16: =VLOOKUP($A16&X$2,Sheet2!$D$1:$F$601,3,0) -> A | Y16: WO | Z16: =VLOOKUP($A16&Z$2,Sheet2!$D$1:$F$601,3,0) -> A | AA16: =VLOOKUP($A16&AA$2,Sheet2!$D$1:$F$601,3,0) -> P | AB16: =VLOOKUP($A16&AB$2,Sheet2!$D$1:$F$601,3,0) -> P | AC16: =VLOOKUP($A16&AC$2,Sheet2!$D$1:$F$601,3,0) -> P | AD16: =VLOOKUP($A16&AD$2,Sheet2!$D$1:$F$601,3,0) -> L | AE16: =VLOOKUP($A16&AE$2,Sheet2!$D$1:$F$601,3,0) -> P | AF16: WO | AG16: =VLOOKUP($A16&AG$2,Sheet2!$D$1:$F$601,3,0) -> A | AH16: =VLOOKUP($A16&AH$2,Sheet2!$D$1:$F$601,3,0) -> L | AI16: =VLOOKUP($A16&AI$2,Sheet2!$D$1:$F$601,3,0) -> P | AJ16: =VLOOKUP($A16&AJ$2,Sheet2!$D$1:$F$601,3,0) -> P | AK16: =VLOOKUP($A16&AK$2,Sheet2!$D$1:$F$601,3,0) -> P | AL16: =VLOOKUP($A16&AL$2,Sheet2!$D$1:$F$601,3,0) -> P | AM16: WO | AN16: =VLOOKUP($A16&AN$2,Sheet2!$D$1:$F$601,3,0) -> P | AO16: =VLOOKUP($A16&AO$2,Sheet2!$D$1:$F$601,3,0) -> P | AP16: =VLOOKUP($A16&AP$2,Sheet2!$D$1:$F$601,3,0) -> P | AQ16: =VLOOKUP($A16&AQ$2,Sheet2!$D$1:$F$601,3,0) -> L | AR16: =VLOOKUP($A16&AR$2,Sheet2!$D$1:$F$601,3,0) -> P | AS16: =VLOOKUP($A16&AS$2,Sheet2!$D$1:$F$601,3,0) -> P | AT16: WO | AU16: =VLOOKUP($A16&AU$2,Sheet2!$D$1:$F$601,3,0) -> P | AV16: =VLOOKUP($A16&AV$2,Sheet2!$D$1:$F$601,3,0) -> A | AW16: =COUNTIF(S16:AV16,"P") -> 18 | AX16: =COUNTIF(S16:AV16,"A") -> 4 | AY16: =COUNTIF(S16:AV16,"H") -> 0 | AZ16: =COUNTIF(S16:AV16,"L") -> 4 | BA16: =COUNTIF(S16:AV16,"WO") -> 4 | BB16: =COUNTIF(S16:AV16,"HO") -> 0 | BC16: =SUM(AW16:BB16)-AX16-IF(AZ16>1,AZ16-1,0)-(AY16/2) -> 23 | BD16: 13000 | BE16: =BD16/30*BC16 -> 9966.6667 | BF16: =BE16*20% -> 1993.3333 | BG16: =BE16*40% -> 3986.6667 | BH16: 1294 | BI16: =VLOOKUP(A16,Sheet3!$A$1:$E$21,5,0) -> 0 | BJ16: =SUM(BE16:BI16) -> 17240.667 | BK16: =IF(SUM(BE16:BF16)>=15000,1800,(SUM(BE16:BF16)*12%)) -> 1435.2 | BL16: =IF(BJ16>21000,0,BJ16*0.75%) -> 129.305 | BM16: =IF(SUM(BE16:BF16)>=15000,550.5,(SUM(BE16:BF16)*3.67%)) -> 438.932 | BN16: =IF(SUM(BE16:BF16)>=15000,1249.5,SUM(BE16:BF16)*8.33%) -> 996.268 | BO16: =IF(BJ16>=21000,0,BJ16*3.25%) -> 560.32167 | BP16: =IF(BJ16>25000,200,IF(BJ16>20000,150,IF(BJ16>15000,100,0))) -> 100 | BQ16: =IF((BJ16*12)<=400000,0, IF((BJ16*12)<=800000,((BJ16*12)-400000)*5%, IF((BJ16*12)<=1200000,20000+((BJ16*12)-800000)*10%, IF((BJ16*12)<=1600000,60000+((BJ16*12)-1200000)*15%, IF((BJ16*12)<=2000000,120000+((BJ16*12)-1600000)*20%, IF((BJ16*12)<=2400000,200000+((BJ16*12)-2000000)*25%, IF((BJ16*12)>2400000,300000+((BJ16*12)-2400000)*30%)))))))/12 -> 0 | BR16: 1000 | BS16: =BJ16-BK16-BL16-BP16-BQ16-BR16 -> 14576.162
A17: E00015 | B17: Rohit Nayak | C17: Manager | D17: Admin | E17: 7889705337 | F17: 403651146579 | G17: 8132165834 | H17: 2609984680 | I17: 8132165834 | J17: 7512787697 | K17: XBWAK3804K | L17: 865743373927 | M17: H.No. 57, Comar Chowk, Hyderabad 909536 | N17: Navi Mumbai | O17: 515446 | P17: 43644 | Q17: Night | R17: saira42@jhaveri.com | S17: =VLOOKUP($A17&S$2,Sheet2!$D$1:$F$601,3,0) -> P | T17: =VLOOKUP($A17&T$2,Sheet2!$D$1:$F$601,3,0) -> P | U17: =VLOOKUP($A17&U$2,Sheet2!$D$1:$F$601,3,0) -> P | V17: =VLOOKUP($A17&V$2,Sheet2!$D$1:$F$601,3,0) -> A | W17: =VLOOKUP($A17&W$2,Sheet2!$D$1:$F$601,3,0) -> P | X17: =VLOOKUP($A17&X$2,Sheet2!$D$1:$F$601,3,0) -> P | Y17: WO | Z17: =VLOOKUP($A17&Z$2,Sheet2!$D$1:$F$601,3,0) -> L | AA17: =VLOOKUP($A17&AA$2,Sheet2!$D$1:$F$601,3,0) -> A | AB17: =VLOOKUP($A17&AB$2,Sheet2!$D$1:$F$601,3,0) -> P | AC17: =VLOOKUP($A17&AC$2,Sheet2!$D$1:$F$601,3,0) -> P | AD17: =VLOOKUP($A17&AD$2,Sheet2!$D$1:$F$601,3,0) -> P | AE17: =VLOOKUP($A17&AE$2,Sheet2!$D$1:$F$601,3,0) -> P | AF17: WO | AG17: =VLOOKUP($A17&AG$2,Sheet2!$D$1:$F$601,3,0) -> P | AH17: =VLOOKUP($A17&AH$2,Sheet2!$D$1:$F$601,3,0) -> P | AI17: =VLOOKUP($A17&AI$2,Sheet2!$D$1:$F$601,3,0) -> L | AJ17: =VLOOKUP($A17&AJ$2,Sheet2!$D$1:$F$601,3,0) -> P | AK17: =VLOOKUP($A17&AK$2,Sheet2!$D$1:$F$601,3,0) -> L | AL17: =VLOOKUP($A17&AL$2,Sheet2!$D$1:$F$601,3,0) -> A | AM17: WO | AN17: =VLOOKUP($A17&AN$2,Sheet2!$D$1:$F$601,3,0) -> L | AO17: =VLOOKUP($A17&AO$2,Sheet2!$D$1:$F$601,3,0) -> A | AP17: =VLOOKUP($A17&AP$2,Sheet2!$D$1:$F$601,3,0) -> P | AQ17: =VLOOKUP($A17&AQ$2,Sheet2!$D$1:$F$601,3,0) -> P | AR17: =VLOOKUP($A17&AR$2,Sheet2!$D$1:$F$601,3,0) -> P | AS17: =VLOOKUP($A17&AS$2,Sheet2!$D$1:$F$601,3,0) -> P | AT17: WO | AU17: =VLOOKUP($A17&AU$2,Sheet2!$D$1:$F$601,3,0) -> L | AV17: =VLOOKUP($A17&AV$2,Sheet2!$D$1:$F$601,3,0) -> P | AW17: =COUNTIF(S17:AV17,"P") -> 17 | AX17: =COUNTIF(S17:AV17,"A") -> 4 | AY17: =COUNTIF(S17:AV17,"H") -> 0 | AZ17: =COUNTIF(S17:AV17,"L") -> 5 | BA17: =COUNTIF(S17:AV17,"WO") -> 4 | BB17: =COUNTIF(S17:AV17,"HO") -> 0 | BC17: =SUM(AW17:BB17)-AX17-IF(AZ17>1,AZ17-1,0)-(AY17/2) -> 22 | BD17: 12000 | BE17: =BD17/30*BC17 -> 8800 | BF17: =BE17*20% -> 1760 | BG17: =BE17*40% -> 3520 | BH17: 2441 | BI17: =VLOOKUP(A17,Sheet3!$A$1:$E$21,5,0) -> 5645.8 | BJ17: =SUM(BE17:BI17) -> 22166.8 | BK17: =IF(SUM(BE17:BF17)>=15000,1800,(SUM(BE17:BF17)*12%)) -> 1267.2 | BL17: =IF(BJ17>21000,0,BJ17*0.75%) -> 0 | BM17: =IF(SUM(BE17:BF17)>=15000,550.5,(SUM(BE17:BF17)*3.67%)) -> 387.552 | BN17: =IF(SUM(BE17:BF17)>=15000,1249.5,SUM(BE17:BF17)*8.33%) -> 879.648 | BO17: =IF(BJ17>=21000,0,BJ17*3.25%) -> 0 | BP17: =IF(BJ17>25000,200,IF(BJ17>20000,150,IF(BJ17>15000,100,0))) -> 150 | BQ17: =IF((BJ17*12)<=400000,0, IF((BJ17*12)<=800000,((BJ17*12)-400000)*5%, IF((BJ17*12)<=1200000,20000+((BJ17*12)-800000)*10%, IF((BJ17*12)<=1600000,60000+((BJ17*12)-1200000)*15%, IF((BJ17*12)<=2000000,120000+((BJ17*12)-1600000)*20%, IF((BJ17*12)<=2400000,200000+((BJ17*12)-2000000)*25%, IF((BJ17*12)>2400000,300000+((BJ17*12)-2400000)*30%)))))))/12 -> 0 | BR17: 0 | BS17: =BJ17-BK17-BL17-BP17-BQ17-BR17 -> 20749.6
A18: E00016 | B18: Suresh Chaudhari | C18: Accountant | D18: Sales | E18: 0490993559 | F18: 540400773491 | G18: 2087024530 | H18: 1087729013 | I18: 2087024530 | J18: 9502070765 | K18: VFDWO8477X | L18: 963565148366 | M18: 03/341, Thaker Road, Silchar-754081 | N18: Karaikudi | O18: 375774 | P18: 44431 | Q18: Day | R18: damini04@bhardwaj-kapur.org | S18: =VLOOKUP($A18&S$2,Sheet2!$D$1:$F$601,3,0) -> A | T18: =VLOOKUP($A18&T$2,Sheet2!$D$1:$F$601,3,0) -> P | U18: =VLOOKUP($A18&U$2,Sheet2!$D$1:$F$601,3,0) -> A | V18: =VLOOKUP($A18&V$2,Sheet2!$D$1:$F$601,3,0) -> A | W18: =VLOOKUP($A18&W$2,Sheet2!$D$1:$F$601,3,0) -> A | X18: =VLOOKUP($A18&X$2,Sheet2!$D$1:$F$601,3,0) -> A | Y18: WO | Z18: =VLOOKUP($A18&Z$2,Sheet2!$D$1:$F$601,3,0) -> P | AA18: =VLOOKUP($A18&AA$2,Sheet2!$D$1:$F$601,3,0) -> P | AB18: =VLOOKUP($A18&AB$2,Sheet2!$D$1:$F$601,3,0) -> P | AC18: =VLOOKUP($A18&AC$2,Sheet2!$D$1:$F$601,3,0) -> P | AD18: =VLOOKUP($A18&AD$2,Sheet2!$D$1:$F$601,3,0) -> A | AE18: =VLOOKUP($A18&AE$2,Sheet2!$D$1:$F$601,3,0) -> P | AF18: WO | AG18: =VLOOKUP($A18&AG$2,Sheet2!$D$1:$F$601,3,0) -> P | AH18: =VLOOKUP($A18&AH$2,Sheet2!$D$1:$F$601,3,0) -> P | AI18: =VLOOKUP($A18&AI$2,Sheet2!$D$1:$F$601,3,0) -> P | AJ18: =VLOOKUP($A18&AJ$2,Sheet2!$D$1:$F$601,3,0) -> A | AK18: =VLOOKUP($A18&AK$2,Sheet2!$D$1:$F$601,3,0) -> P | AL18: =VLOOKUP($A18&AL$2,Sheet2!$D$1:$F$601,3,0) -> A | AM18: WO | AN18: =VLOOKUP($A18&AN$2,Sheet2!$D$1:$F$601,3,0) -> P | AO18: =VLOOKUP($A18&AO$2,Sheet2!$D$1:$F$601,3,0) -> P | AP18: =VLOOKUP($A18&AP$2,Sheet2!$D$1:$F$601,3,0) -> P | AQ18: =VLOOKUP($A18&AQ$2,Sheet2!$D$1:$F$601,3,0) -> A | AR18: =VLOOKUP($A18&AR$2,Sheet2!$D$1:$F$601,3,0) -> P | AS18: =VLOOKUP($A18&AS$2,Sheet2!$D$1:$F$601,3,0) -> P | AT18: WO | AU18: =VLOOKUP($A18&AU$2,Sheet2!$D$1:$F$601,3,0) -> P | AV18: =VLOOKUP($A18&AV$2,Sheet2!$D$1:$F$601,3,0) -> L | AW18: =COUNTIF(S18:AV18,"P") -> 16 | AX18: =COUNTIF(S18:AV18,"A") -> 9 | AY18: =COUNTIF(S18:AV18,"H") -> 0 | AZ18: =COUNTIF(S18:AV18,"L") -> 1 | BA18: =COUNTIF(S18:AV18,"WO") -> 4 | BB18: =COUNTIF(S18:AV18,"HO") -> 0 | BC18: =SUM(AW18:BB18)-AX18-IF(AZ18>1,AZ18-1,0)-(AY18/2) -> 21 | BD18: 32654 | BE18: =BD18/30*BC18 -> 22857.8 | BF18: =BE18*20% -> 4571.56 | BG18: =BE18*40% -> 9143.12 | BH18: 2458 | BI18: =VLOOKUP(A18,Sheet3!$A$1:$E$21,5,0) -> 0 | BJ18: =SUM(BE18:BI18) -> 39030.48 | BK18: =IF(SUM(BE18:BF18)>=15000,1800,(SUM(BE18:BF18)*12%)) -> 1800 | BL18: =IF(BJ18>21000,0,BJ18*0.75%) -> 0 | BM18: =IF(SUM(BE18:BF18)>=15000,550.5,(SUM(BE18:BF18)*3.67%)) -> 550.5 | BN18: =IF(SUM(BE18:BF18)>=15000,1249.5,SUM(BE18:BF18)*8.33%) -> 1249.5 | BO18: =IF(BJ18>=21000,0,BJ18*3.25%) -> 0 | BP18: =IF(BJ18>25000,200,IF(BJ18>20000,150,IF(BJ18>15000,100,0))) -> 200 | BQ18: =IF((BJ18*12)<=400000,0, IF((BJ18*12)<=800000,((BJ18*12)-400000)*5%, IF((BJ18*12)<=1200000,20000+((BJ18*12)-800000)*10%, IF((BJ18*12)<=1600000,60000+((BJ18*12)-1200000)*15%, IF((BJ18*12)<=2000000,120000+((BJ18*12)-1600000)*20%, IF((BJ18*12)<=2400000,200000+((BJ18*12)-2000000)*25%, IF((BJ18*12)>2400000,300000+((BJ18*12)-2400000)*30%)))))))/12 -> 284.85733 | BR18: 0 | BS18: =BJ18-BK18-BL18-BP18-BQ18-BR18 -> 36745.623
A19: E00017 | B19: Vijay Shukla | C19: Executive | D19: Admin | E19: 4946465197 | F19: 221535456456 | G19: 3010506846 | H19: 7564733213 | I19: 3010506846 | J19: 1095365992 | K19: OBBDA4950A | L19: 985503373716 | M19: H.No. 01, Ramachandran Zila, Karawal Nagar-312258 | N19: Bhilwara | O19: 369582 | P19: 42482 | Q19: Night | R19: sankaranarhaan@krish.org | S19: =VLOOKUP($A19&S$2,Sheet2!$D$1:$F$601,3,0) -> P | T19: =VLOOKUP($A19&T$2,Sheet2!$D$1:$F$601,3,0) -> L | U19: =VLOOKUP($A19&U$2,Sheet2!$D$1:$F$601,3,0) -> P | V19: =VLOOKUP($A19&V$2,Sheet2!$D$1:$F$601,3,0) -> A | W19: =VLOOKUP($A19&W$2,Sheet2!$D$1:$F$601,3,0) -> P | X19: =VLOOKUP($A19&X$2,Sheet2!$D$1:$F$601,3,0) -> P | Y19: WO | Z19: =VLOOKUP($A19&Z$2,Sheet2!$D$1:$F$601,3,0) -> L | AA19: =VLOOKUP($A19&AA$2,Sheet2!$D$1:$F$601,3,0) -> L | AB19: =VLOOKUP($A19&AB$2,Sheet2!$D$1:$F$601,3,0) -> L | AC19: =VLOOKUP($A19&AC$2,Sheet2!$D$1:$F$601,3,0) -> P | AD19: =VLOOKUP($A19&AD$2,Sheet2!$D$1:$F$601,3,0) -> P | AE19: =VLOOKUP($A19&AE$2,Sheet2!$D$1:$F$601,3,0) -> P | AF19: WO | AG19: =VLOOKUP($A19&AG$2,Sheet2!$D$1:$F$601,3,0) -> P | AH19: =VLOOKUP($A19&AH$2,Sheet2!$D$1:$F$601,3,0) -> A | AI19: =VLOOKUP($A19&AI$2,Sheet2!$D$1:$F$601,3,0) -> P | AJ19: =VLOOKUP($A19&AJ$2,Sheet2!$D$1:$F$601,3,0) -> P | AK19: =VLOOKUP($A19&AK$2,Sheet2!$D$1:$F$601,3,0) -> P | AL19: =VLOOKUP($A19&AL$2,Sheet2!$D$1:$F$601,3,0) -> P | AM19: WO | AN19: =VLOOKUP($A19&AN$2,Sheet2!$D$1:$F$601,3,0) -> A | AO19: =VLOOKUP($A19&AO$2,Sheet2!$D$1:$F$601,3,0) -> P | AP19: =VLOOKUP($A19&AP$2,Sheet2!$D$1:$F$601,3,0) -> P | AQ19: =VLOOKUP($A19&AQ$2,Sheet2!$D$1:$F$601,3,0) -> P | AR19: =VLOOKUP($A19&AR$2,Sheet2!$D$1:$F$601,3,0) -> P | AS19: =VLOOKUP($A19&AS$2,Sheet2!$D$1:$F$601,3,0) -> L | AT19: WO | AU19: =VLOOKUP($A19&AU$2,Sheet2!$D$1:$F$601,3,0) -> P | AV19: =VLOOKUP($A19&AV$2,Sheet2!$D$1:$F$601,3,0) -> P | AW19: =COUNTIF(S19:AV19,"P") -> 18 | AX19: =COUNTIF(S19:AV19,"A") -> 3 | AY19: =COUNTIF(S19:AV19,"H") -> 0 | AZ19: =COUNTIF(S19:AV19,"L") -> 5 | BA19: =COUNTIF(S19:AV19,"WO") -> 4 | BB19: =COUNTIF(S19:AV19,"HO") -> 0 | BC19: =SUM(AW19:BB19)-AX19-IF(AZ19>1,AZ19-1,0)-(AY19/2) -> 23 | BD19: 16000 | BE19: =BD19/30*BC19 -> 12266.667 | BF19: =BE19*20% -> 2453.3333 | BG19: =BE19*40% -> 4906.6667 | BH19: 1733 | BI19: =VLOOKUP(A19,Sheet3!$A$1:$E$21,5,0) -> 0 | BJ19: =SUM(BE19:BI19) -> 21359.667 | BK19: =IF(SUM(BE19:BF19)>=15000,1800,(SUM(BE19:BF19)*12%)) -> 1766.4 | BL19: =IF(BJ19>21000,0,BJ19*0.75%) -> 0 | BM19: =IF(SUM(BE19:BF19)>=15000,550.5,(SUM(BE19:BF19)*3.67%)) -> 540.224 | BN19: =IF(SUM(BE19:BF19)>=15000,1249.5,SUM(BE19:BF19)*8.33%) -> 1226.176 | BO19: =IF(BJ19>=21000,0,BJ19*3.25%) -> 0 | BP19: =IF(BJ19>25000,200,IF(BJ19>20000,150,IF(BJ19>15000,100,0))) -> 150 | BQ19: =IF((BJ19*12)<=400000,0, IF((BJ19*12)<=800000,((BJ19*12)-400000)*5%, IF((BJ19*12)<=1200000,20000+((BJ19*12)-800000)*10%, IF((BJ19*12)<=1600000,60000+((BJ19*12)-1200000)*15%, IF((BJ19*12)<=2000000,120000+((BJ19*12)-1600000)*20%, IF((BJ19*12)<=2400000,200000+((BJ19*12)-2000000)*25%, IF((BJ19*12)>2400000,300000+((BJ19*12)-2400000)*30%)))))))/12 -> 0 | BR19: 0 | BS19: =BJ19-BK19-BL19-BP19-BQ19-BR19 -> 19443.267
A20: E00018 | B20: Raj Chopra | C20: Accountant | D20: Admin | E20: 4570194171 | F20: 356977270812 | G20: 6156278088 | H20: 6572169474 | I20: 6156278088 | J20: 5846863942 | K20: NRXNW6482V | L20: 477691099666 | M20: H.No. 134, Korpal Ganj, Malda 247129 | N20: Rampur | O20: 860387 | P20: 44293 | Q20: Day | R20: eviswanathan@bhatia.com | S20: =VLOOKUP($A20&S$2,Sheet2!$D$1:$F$601,3,0) -> L | T20: =VLOOKUP($A20&T$2,Sheet2!$D$1:$F$601,3,0) -> A | U20: =VLOOKUP($A20&U$2,Sheet2!$D$1:$F$601,3,0) -> P | V20: =VLOOKUP($A20&V$2,Sheet2!$D$1:$F$601,3,0) -> L | W20: =VLOOKUP($A20&W$2,Sheet2!$D$1:$F$601,3,0) -> P | X20: =VLOOKUP($A20&X$2,Sheet2!$D$1:$F$601,3,0) -> P | Y20: WO | Z20: =VLOOKUP($A20&Z$2,Sheet2!$D$1:$F$601,3,0) -> P | AA20: =VLOOKUP($A20&AA$2,Sheet2!$D$1:$F$601,3,0) -> P | AB20: =VLOOKUP($A20&AB$2,Sheet2!$D$1:$F$601,3,0) -> A | AC20: =VLOOKUP($A20&AC$2,Sheet2!$D$1:$F$601,3,0) -> P | AD20: =VLOOKUP($A20&AD$2,Sheet2!$D$1:$F$601,3,0) -> P | AE20: =VLOOKUP($A20&AE$2,Sheet2!$D$1:$F$601,3,0) -> P | AF20: WO | AG20: =VLOOKUP($A20&AG$2,Sheet2!$D$1:$F$601,3,0) -> P | AH20: =VLOOKUP($A20&AH$2,Sheet2!$D$1:$F$601,3,0) -> P | AI20: =VLOOKUP($A20&AI$2,Sheet2!$D$1:$F$601,3,0) -> A | AJ20: =VLOOKUP($A20&AJ$2,Sheet2!$D$1:$F$601,3,0) -> P | AK20: =VLOOKUP($A20&AK$2,Sheet2!$D$1:$F$601,3,0) -> P | AL20: =VLOOKUP($A20&AL$2,Sheet2!$D$1:$F$601,3,0) -> L | AM20: WO | AN20: =VLOOKUP($A20&AN$2,Sheet2!$D$1:$F$601,3,0) -> P | AO20: =VLOOKUP($A20&AO$2,Sheet2!$D$1:$F$601,3,0) -> P | AP20: =VLOOKUP($A20&AP$2,Sheet2!$D$1:$F$601,3,0) -> P | AQ20: =VLOOKUP($A20&AQ$2,Sheet2!$D$1:$F$601,3,0) -> P | AR20: =VLOOKUP($A20&AR$2,Sheet2!$D$1:$F$601,3,0) -> P | AS20: =VLOOKUP($A20&AS$2,Sheet2!$D$1:$F$601,3,0) -> P | AT20: WO | AU20: =VLOOKUP($A20&AU$2,Sheet2!$D$1:$F$601,3,0) -> P | AV20: =VLOOKUP($A20&AV$2,Sheet2!$D$1:$F$601,3,0) -> A | AW20: =COUNTIF(S20:AV20,"P") -> 19 | AX20: =COUNTIF(S20:AV20,"A") -> 4 | AY20: =COUNTIF(S20:AV20,"H") -> 0 | AZ20: =COUNTIF(S20:AV20,"L") -> 3 | BA20: =COUNTIF(S20:AV20,"WO") -> 4 | BB20: =COUNTIF(S20:AV20,"HO") -> 0 | BC20: =SUM(AW20:BB20)-AX20-IF(AZ20>1,AZ20-1,0)-(AY20/2) -> 24 | BD20: 16000 | BE20: =BD20/30*BC20 -> 12800 | BF20: =BE20*20% -> 2560 | BG20: =BE20*40% -> 5120 | BH20: 2369 | BI20: =VLOOKUP(A20,Sheet3!$A$1:$E$21,5,0) -> 0 | BJ20: =SUM(BE20:BI20) -> 22849 | BK20: =IF(SUM(BE20:BF20)>=15000,1800,(SUM(BE20:BF20)*12%)) -> 1800 | BL20: =IF(BJ20>21000,0,BJ20*0.75%) -> 0 | BM20: =IF(SUM(BE20:BF20)>=15000,550.5,(SUM(BE20:BF20)*3.67%)) -> 550.5 | BN20: =IF(SUM(BE20:BF20)>=15000,1249.5,SUM(BE20:BF20)*8.33%) -> 1249.5 | BO20: =IF(BJ20>=21000,0,BJ20*3.25%) -> 0 | BP20: =IF(BJ20>25000,200,IF(BJ20>20000,150,IF(BJ20>15000,100,0))) -> 150 | BQ20: =IF((BJ20*12)<=400000,0, IF((BJ20*12)<=800000,((BJ20*12)-400000)*5%, IF((BJ20*12)<=1200000,20000+((BJ20*12)-800000)*10%, IF((BJ20*12)<=1600000,60000+((BJ20*12)-1200000)*15%, IF((BJ20*12)<=2000000,120000+((BJ20*12)-1600000)*20%, IF((BJ20*12)<=2400000,200000+((BJ20*12)-2000000)*25%, IF((BJ20*12)>2400000,300000+((BJ20*12)-2400000)*30%)))))))/12 -> 0 | BR20: 0 | BS20: =BJ20-BK20-BL20-BP20-BQ20-BR20 -> 20899
A21: E00019 | B21: Arjun Joshi | C21: Officer | D21: IT | E21: 6291079775 | F21: 473210180239 | G21: 7408432483 | H21: 3610967467 | I21: 7408432483 | J21: 2557177995 | K21: BZCJY7213K | L21: 597078746973 | M21: H.No. 695, Garg Road, Gandhidham-754576 | N21: Ahmedabad | O21: 964787 | P21: 42308 | Q21: Day | R21: aaina37@gmail.com | S21: =VLOOKUP($A21&S$2,Sheet2!$D$1:$F$601,3,0) -> P | T21: =VLOOKUP($A21&T$2,Sheet2!$D$1:$F$601,3,0) -> L | U21: =VLOOKUP($A21&U$2,Sheet2!$D$1:$F$601,3,0) -> P | V21: =VLOOKUP($A21&V$2,Sheet2!$D$1:$F$601,3,0) -> L | W21: =VLOOKUP($A21&W$2,Sheet2!$D$1:$F$601,3,0) -> P | X21: =VLOOKUP($A21&X$2,Sheet2!$D$1:$F$601,3,0) -> P | Y21: WO | Z21: =VLOOKUP($A21&Z$2,Sheet2!$D$1:$F$601,3,0) -> P | AA21: =VLOOKUP($A21&AA$2,Sheet2!$D$1:$F$601,3,0) -> A | AB21: =VLOOKUP($A21&AB$2,Sheet2!$D$1:$F$601,3,0) -> P | AC21: =VLOOKUP($A21&AC$2,Sheet2!$D$1:$F$601,3,0) -> P | AD21: =VLOOKUP($A21&AD$2,Sheet2!$D$1:$F$601,3,0) -> L | AE21: =VLOOKUP($A21&AE$2,Sheet2!$D$1:$F$601,3,0) -> A | AF21: WO | AG21: =VLOOKUP($A21&AG$2,Sheet2!$D$1:$F$601,3,0) -> P | AH21: =VLOOKUP($A21&AH$2,Sheet2!$D$1:$F$601,3,0) -> P | AI21: =VLOOKUP($A21&AI$2,Sheet2!$D$1:$F$601,3,0) -> P | AJ21: =VLOOKUP($A21&AJ$2,Sheet2!$D$1:$F$601,3,0) -> A | AK21: =VLOOKUP($A21&AK$2,Sheet2!$D$1:$F$601,3,0) -> L | AL21: =VLOOKUP($A21&AL$2,Sheet2!$D$1:$F$601,3,0) -> A | AM21: WO | AN21: =VLOOKUP($A21&AN$2,Sheet2!$D$1:$F$601,3,0) -> L | AO21: =VLOOKUP($A21&AO$2,Sheet2!$D$1:$F$601,3,0) -> P | AP21: =VLOOKUP($A21&AP$2,Sheet2!$D$1:$F$601,3,0) -> P | AQ21: =VLOOKUP($A21&AQ$2,Sheet2!$D$1:$F$601,3,0) -> A | AR21: =VLOOKUP($A21&AR$2,Sheet2!$D$1:$F$601,3,0) -> P | AS21: =VLOOKUP($A21&AS$2,Sheet2!$D$1:$F$601,3,0) -> P | AT21: WO | AU21: =VLOOKUP($A21&AU$2,Sheet2!$D$1:$F$601,3,0) -> P | AV21: =VLOOKUP($A21&AV$2,Sheet2!$D$1:$F$601,3,0) -> P | AW21: =COUNTIF(S21:AV21,"P") -> 16 | AX21: =COUNTIF(S21:AV21,"A") -> 5 | AY21: =COUNTIF(S21:AV21,"H") -> 0 | AZ21: =COUNTIF(S21:AV21,"L") -> 5 | BA21: =COUNTIF(S21:AV21,"WO") -> 4 | BB21: =COUNTIF(S21:AV21,"HO") -> 0 | BC21: =SUM(AW21:BB21)-AX21-IF(AZ21>1,AZ21-1,0)-(AY21/2) -> 21 | BD21: 16000 | BE21: =BD21/30*BC21 -> 11200 | BF21: =BE21*20% -> 2240 | BG21: =BE21*40% -> 4480 | BH21: 2209 | BI21: =VLOOKUP(A21,Sheet3!$A$1:$E$21,5,0) -> 0 | BJ21: =SUM(BE21:BI21) -> 20129 | BK21: =IF(SUM(BE21:BF21)>=15000,1800,(SUM(BE21:BF21)*12%)) -> 1612.8 | BL21: =IF(BJ21>21000,0,BJ21*0.75%) -> 150.9675 | BM21: =IF(SUM(BE21:BF21)>=15000,550.5,(SUM(BE21:BF21)*3.67%)) -> 493.248 | BN21: =IF(SUM(BE21:BF21)>=15000,1249.5,SUM(BE21:BF21)*8.33%) -> 1119.552 | BO21: =IF(BJ21>=21000,0,BJ21*3.25%) -> 654.1925 | BP21: =IF(BJ21>25000,200,IF(BJ21>20000,150,IF(BJ21>15000,100,0))) -> 150 | BQ21: =IF((BJ21*12)<=400000,0, IF((BJ21*12)<=800000,((BJ21*12)-400000)*5%, IF((BJ21*12)<=1200000,20000+((BJ21*12)-800000)*10%, IF((BJ21*12)<=1600000,60000+((BJ21*12)-1200000)*15%, IF((BJ21*12)<=2000000,120000+((BJ21*12)-1600000)*20%, IF((BJ21*12)<=2400000,200000+((BJ21*12)-2000000)*25%, IF((BJ21*12)>2400000,300000+((BJ21*12)-2400000)*30%)))))))/12 -> 0 | BR21: 0 | BS21: =BJ21-BK21-BL21-BP21-BQ21-BR21 -> 18215.233
